Workbook
Name _______DAT10: #REF!
Name _______DAT11: #REF!
Name _______DAT12: #REF!
Name _______DAT13: #REF!
Name _______DAT14: #REF!
Name _______DAT15: #REF!
Name _______DAT16: #REF!
Name _______DAT17: #REF!
Name _______DAT18: #REF!
Name _______DAT19: #REF!
Name _______DAT2: #REF!
Name _______DAT20: #REF!
Name _______DAT22: #REF!
Name _______DAT23: #REF!
Name _______DAT24: #REF!
Name _______DAT26: #REF!
Name _______DAT27: #REF!
Name _______DAT28: #REF!
Name _______DAT29: #REF!
Name _______DAT3: #REF!
Name _______DAT30: #REF!
Name _______DAT31: #REF!
Name _______DAT32: #REF!
Name _______DAT33: #REF!
Name _______DAT34: #REF!
Name _______DAT35: #REF!
Name _______DAT36: #REF!
Name _______DAT37: #REF!
Name _______DAT38: #REF!
Name _______DAT39: #REF!
Name _______DAT4: #REF!
Name _______DAT40: #REF!
Name _______DAT41: #REF!
Name _______DAT42: #REF!
Name _______DAT43: #REF!
Name _______DAT44: #REF!
Name _______DAT45: #REF!
Name _______DAT46: #REF!
Name _______DAT47: #REF!
Name _______DAT48: #REF!
Name _______DAT5: #REF!
Name _______DAT6: #REF!
Name _______DAT7: #REF!
Name _______DAT8: #REF!
Name _______DAT9: #REF!
Name ______DAT1: #REF!
Name ______DAT10: #REF!
Name ______DAT11: #REF!
Name ______DAT12: #REF!
Name ______DAT13: #REF!
Name ______DAT14: #REF!
Name ______DAT15: #REF!
Name ______DAT16: #REF!
Name ______DAT17: #REF!
Name ______DAT18: #REF!
Name ______DAT19: #REF!
Name ______DAT2: #REF!
Name ______DAT20: #REF!
Name ______DAT21: #REF!
Name ______DAT22: #REF!

Sheet Scope 1
AU1: 2022 | AV1: 2023 | AW1: 2024
B2: Fuel/Raw Material Usage and Waste Incineration Activity Data | AT2: Total Scope 1 Emissions | AU2: =SUMIF($Y$6:$Y$79,"2022",$AT$6:$AT$79) -> 5807.3723 | AV2: =SUMIF($Y$6:$Y$79,"2023",$AT$6:$AT$79) -> 5472.6179 | AW2: =SUMIF($Y$6:$Y$79,"2024",$AT$6:$AT$79) -> 5415.5677
B4: No | D4: Information of Entity/Facility Site | E4: Fuel Usage Information | Y4: Deloitte_raw data 보완 | AS4: Emissions calculation
B5: No | C5: Name of Entity | D5: Name of Facility | E5: Name of Own facility | F5: Classification of Fuel/Raw Material | G5: Emissions Activities | H5: Detailed Description | I5: Types of fuel | J5: Detailed Description of Fuel/Raw Material | K5: Fuel usage | L5: Jan | M5: Feb | N5: Mar | O5: Apr | P5: May | Q5: Jun | R5: Jul | S5: Aug | T5: Sep | U5: Oct | V5: Nov | W5: Dec | X5: Unit | Y5: Data Collection Year | Z5: Name of Own facility | AA5: Combustion Type | AB5: Types of fuel | AC5: Jan | AD5: Feb | AE5: Mar | AF5: Apr | AG5: May | AH5: Jun | AI5: Jul | AJ5: Aug | AK5: Sep | AL5: Oct | AM5: Nov | AN5: Dec | AO5: For Review | AP5: Fuel usage | AQ5: Unit | AR5: Fuel Consumption (kg) | AS5: Energy Consumption (MJ) | AT5: GHG Emissions (tCO2eq) | AU5: kgCO2 | AV5: kgCH4 | AW5: kgN2O
B6: 1 | C6: HOJEON LIMITED | D6: HOJEON LIMITED Co., Ltd | E6: Vehicle | F6: Fuel | G6: Mobile combustion | H6: 차량 운행 | I6: Automotive gasoline (petrol) | K6: 21.896259 | L6: 1.7928166 | M6: 1.6324213 | N6: 1.6471847 | O6: 2.0347238 | P6: 1.9814761 | Q6: 1.5390641 | R6: 2.0951131 | S6: 2.0864833 | T6: 2.0737647 | U6: 1.5738172 | V6: 1.347481 | W6: 2.0919136 | X6: ㎥ | Y6: 2022 | Z6: =VLOOKUP($E6,'[1]5-2. Emission Facility'!$B$7:$D$16,2,0) -> Vehicle | AA6: =VLOOKUP($Z6,'[1]5-2. Emission Facility'!$C$7:$D$16,2,0) -> Mobile combustion | AB6: =IF($C6="","",IF(VLOOKUP($C6,'[1]1. General Facility Information'!$C$7:$E$13,3,0)="Korea",'Scope 1'!$I6,INDEX('[1]5-1. Fuel Density'!$B$6:$B$18,MATCH('Scope 1'!$I6,'[1]5-1. Fuel Density'!$C$6:$C$18,0)))) -> Automotive gasoline (petrol) | AC6: =IF(OR($X6="㎥",$X6="kg"),$L6,"") -> 1.7928166 | AD6: =IF(OR($X6="㎥",$X6="kg"),M6,"") -> 1.6324213 | AE6: =IF(OR($X6="㎥",$X6="kg"),N6,"") -> 1.6471847 | AF6: =IF(OR($X6="㎥",$X6="kg"),O6,"") -> 2.0347238 | AG6: =IF(OR($X6="㎥",$X6="kg"),P6,"") -> 1.9814761 | AH6: =IF(OR($X6="㎥",$X6="kg"),Q6,"") -> 1.5390641 | AI6: =IF(OR($X6="㎥",$X6="kg"),R6,"") -> 2.0951131 | AJ6: =IF(OR($X6="㎥",$X6="kg"),S6,"") -> 2.0864833 | AK6: =IF(OR($X6="㎥",$X6="kg"),T6,"") -> 2.0737647 | ... AN6: =IF(OR($X6="㎥",$X6="kg"),W6,"") -> 2.0919136 | AO6: =IF(SUM(AC6:AN6)-AP6=0,"","X") | AP6: =IF(OR($X6="㎥",$X6="kg"),$K6,"") -> 21.896259 | AQ6: =IF(OR($X6="㎥",$X6="kg"),$X6,"") -> ㎥ | AR6: =IF($C6="","",$AP6*IF($AQ6="㎥",VLOOKUP('Scope 1'!AQ6,'[1]5-3. Unit Conversion'!$B$5:$J$13,3,FALSE)*VLOOKUP('Scope 1'!AB6,'[1]5-1. Fuel Density'!$B$6:$D$18,3,FALSE)*1000,IF($AQ6="kg",VLOOKUP('Scope 1'!AQ6,'[1]5-3. Unit Conversion'!$B$16:$G$21,3,FALSE),0))) -> 16225.128 | AS6: =IFERROR(IF($AB6="","",IF(VLOOKUP($AB6,'[1]5-1. Fuel Density'!$B$6:$G$19,6,0)="Use of other GHGs",0,IF($AB6="Industrial Wastes",$AR6*'[1]5-4. Calorific&Emission factor'!$R$75,$AR6*VLOOKUP($AB6,'[1]5-4. Calorific&Emission factor'!$P$9:$R$74,3,FALSE)))),0) -> 718773.18 | AT6: =IF($AB6="","",IF(OR($AB6="Hydrofluorocarbons(HFCs)",$AB6="ETC"),$AR6*VLOOKUP($J6,'[1]5-4. Calorific&Emission factor'!$B$10:$D$14,3,0)/1000,IF(VLOOKUP($AB6,'[1]5-1. Fuel Density'!$B$6:$G$19,6,0)="Use of other GHGs",$AU6/1000,(($AU6*'[1]5-4. Calorific&Emission factor'!$D$7)+($AV6*'[1]5-4. Calorific&Emission factor'!$D$8)+($AW6*'[1]5-4. Calorific&Emission factor'!$D$9))/1000))) -> 49.986937 | AU6: =IF($AB6="","",IF(VLOOKUP($AB6,'[1]5-1. Fuel Density'!$B$6:$G$19,6,0)="Use of other GHGs",$AR6*VLOOKUP($AB6,'[1]5-4. Calorific&Emission factor'!$O$9:$Y$74,5,FALSE)/1000000,$AS6*VLOOKUP($AB6,'[1]5-4. Calorific&Emission factor'!$P$9:$Y$74,4,FALSE)/1000000)) -> 49810.981 | AV6: =IF($AB6="","",IF(VLOOKUP($AB6,'[1]5-1. Fuel Density'!$B$6:$G$19,6,0)="Use of other GHGs",0,$AS6*VLOOKUP($AB6,'[1]5-4. Calorific&Emission factor'!$P$9:$Y$74,6,FALSE)/1000000)) -> 2.1563195 | AW6: =IF($AB6="","",IF(VLOOKUP($AB6,'[1]5-1. Fuel Density'!$B$6:$G$19,6,0)="Use of other GHGs",0,$AS6*VLOOKUP($AB6,'[1]5-4. Calorific&Emission factor'!$P$9:$Y$74,9,FALSE)/1000000)) -> 0.43126391
B7: 2 | C7: PT. KAHOINDAH CITRAGARMENT | D7: KAHOINDAH CITRAGARMENT | E7: Vehicle | F7: Fuel | G7: Mobile combustion fuels and vehicle | H7: manager-level operational vehicles | I7: Automotive gasoline (petrol) | J7: RON 90 (called Pertalite) | K7: 30.25447 | L7: 2.6508 | M7: 1.94136 | N7: 2.56895 | O7: 2.61433 | P7: 1.80482 | Q7: 2.89079 | R7: 2.89508 | S7: 2.83213 | T7: 2.59511 | U7: 2.39294 | V7: 2.50454 | W7: 2.56362 | X7: ㎥ | Y7: 2022 | Z7: =VLOOKUP($E7,'[1]5-2. Emission Facility'!$B$7:$D$16,2,0) -> Vehicle | AA7: =VLOOKUP($Z7,'[1]5-2. Emission Facility'!$C$7:$D$16,2,0) -> Mobile combustion | AB7: =IF($C7="","",IF(VLOOKUP($C7,'[1]1. General Facility Information'!$C$7:$E$13,3,0)="Korea",'Scope 1'!$I7,INDEX('[1]5-1. Fuel Density'!$B$6:$B$18,MATCH('Scope 1'!$I7,'[1]5-1. Fuel Density'!$C$6:$C$18,0)))) -> Automotive gasoline (petrol) | AC7: =IF(OR($X7="㎥",$X7="kg"),$L7,"") -> 2.6508 | AD7: =IF(OR($X7="㎥",$X7="kg"),M7,"") -> 1.94136 | AE7: =IF(OR($X7="㎥",$X7="kg"),N7,"") -> 2.56895 | AF7: =IF(OR($X7="㎥",$X7="kg"),O7,"") -> 2.61433 | AG7: =IF(OR($X7="㎥",$X7="kg"),P7,"") -> 1.80482 | AH7: =IF(OR($X7="㎥",$X7="kg"),Q7,"") -> 2.89079 | AI7: =IF(OR($X7="㎥",$X7="kg"),R7,"") -> 2.89508 | AJ7: =IF(OR($X7="㎥",$X7="kg"),S7,"") -> 2.83213 | AK7: =IF(OR($X7="㎥",$X7="kg"),T7,"") -> 2.59511 | ... AN7: =IF(OR($X7="㎥",$X7="kg"),W7,"") -> 2.56362 | AO7: =IF(SUM(AC7:AN7)-AP7=0,"","X") | AP7: =IF(OR($X7="㎥",$X7="kg"),$K7,"") -> 30.25447 | AQ7: =IF(OR($X7="㎥",$X7="kg"),$X7,"") -> ㎥ | AR7: =IF($C7="","",$AP7*IF($AQ7="㎥",VLOOKUP('Scope 1'!AQ7,'[1]5-3. Unit Conversion'!$B$5:$J$13,3,FALSE)*VLOOKUP('Scope 1'!AB7,'[1]5-1. Fuel Density'!$B$6:$D$18,3,FALSE)*1000,IF($AQ7="kg",VLOOKUP('Scope 1'!AQ7,'[1]5-3. Unit Conversion'!$B$16:$G$21,3,FALSE),0))) -> 22418.562 | AS7: =IFERROR(IF($AB7="","",IF(VLOOKUP($AB7,'[1]5-1. Fuel Density'!$B$6:$G$19,6,0)="Use of other GHGs",0,IF($AB7="Industrial Wastes",$AR7*'[1]5-4. Calorific&Emission factor'!$R$75,$AR7*VLOOKUP($AB7,'[1]5-4. Calorific&Emission factor'!$P$9:$R$74,3,FALSE)))),0) -> 993142.31 | AT7: =IF($AB7="","",IF(OR($AB7="Hydrofluorocarbons(HFCs)",$AB7="ETC"),$AR7*VLOOKUP($J7,'[1]5-4. Calorific&Emission factor'!$B$10:$D$14,3,0)/1000,IF(VLOOKUP($AB7,'[1]5-1. Fuel Density'!$B$6:$G$19,6,0)="Use of other GHGs",$AU7/1000,(($AU7*'[1]5-4. Calorific&Emission factor'!$D$7)+($AV7*'[1]5-4. Calorific&Emission factor'!$D$8)+($AW7*'[1]5-4. Calorific&Emission factor'!$D$9))/1000))) -> 69.067883 | AU7: =IF($AB7="","",IF(VLOOKUP($AB7,'[1]5-1. Fuel Density'!$B$6:$G$19,6,0)="Use of other GHGs",$AR7*VLOOKUP($AB7,'[1]5-4. Calorific&Emission factor'!$O$9:$Y$74,5,FALSE)/1000000,$AS7*VLOOKUP($AB7,'[1]5-4. Calorific&Emission factor'!$P$9:$Y$74,4,FALSE)/1000000)) -> 68824.762 | AV7: =IF($AB7="","",IF(VLOOKUP($AB7,'[1]5-1. Fuel Density'!$B$6:$G$19,6,0)="Use of other GHGs",0,$AS7*VLOOKUP($AB7,'[1]5-4. Calorific&Emission factor'!$P$9:$Y$74,6,FALSE)/1000000)) -> 2.9794269 | AW7: =IF($AB7="","",IF(VLOOKUP($AB7,'[1]5-1. Fuel Density'!$B$6:$G$19,6,0)="Use of other GHGs",0,$AS7*VLOOKUP($AB7,'[1]5-4. Calorific&Emission factor'!$P$9:$Y$74,9,FALSE)/1000000)) -> 0.59588539
B8: 3 | C8: PT. KAHOINDAH CITRAGARMENT | D8: KAHOINDAH CITRAGARMENT | E8: Boiler | F8: Fuel | G8: Stationary combustion fuels and equipment - Solid Fuel | H8: converts boiler combustion to produce heat that is used for steam ironing and fabric relaxation. | I8: Industrial Wastes | J8: Fabric Waste from Production | K8: 323390 | L8: 24973 | M8: 22164 | N8: 29643 | O8: 26953 | P8: 19481 | Q8: 26867 | R8: 24545 | S8: 27071 | T8: 31734 | U8: 29833 | V8: 30496 | W8: 29630 | X8: kg | Y8: 2022 | Z8: =VLOOKUP($E8,'[1]5-2. Emission Facility'!$B$7:$D$16,2,0) -> Boiler | AA8: =VLOOKUP($Z8,'[1]5-2. Emission Facility'!$C$7:$D$16,2,0) -> Stationary Combustion | AB8: =IF($C8="","",IF(VLOOKUP($C8,'[1]1. General Facility Information'!$C$7:$E$13,3,0)="Korea",'Scope 1'!$I8,INDEX('[1]5-1. Fuel Density'!$B$6:$B$18,MATCH('Scope 1'!$I8,'[1]5-1. Fuel Density'!$C$6:$C$18,0)))) -> Industrial Wastes | AC8: =IF(OR($X8="㎥",$X8="kg"),$L8,"") -> 24973 | AD8: =IF(OR($X8="㎥",$X8="kg"),M8,"") -> 22164 | AE8: =IF(OR($X8="㎥",$X8="kg"),N8,"") -> 29643 | AF8: =IF(OR($X8="㎥",$X8="kg"),O8,"") -> 26953 | AG8: =IF(OR($X8="㎥",$X8="kg"),P8,"") -> 19481 | AH8: =IF(OR($X8="㎥",$X8="kg"),Q8,"") -> 26867 | AI8: =IF(OR($X8="㎥",$X8="kg"),R8,"") -> 24545 | AJ8: =IF(OR($X8="㎥",$X8="kg"),S8,"") -> 27071 | AK8: =IF(OR($X8="㎥",$X8="kg"),T8,"") -> 31734 | ... AN8: =IF(OR($X8="㎥",$X8="kg"),W8,"") -> 29630 | AO8: =IF(SUM(AC8:AN8)-AP8=0,"","X") | AP8: =IF(OR($X8="㎥",$X8="kg"),$K8,"") -> 323390 | AQ8: =IF(OR($X8="㎥",$X8="kg"),$X8,"") -> kg | AR8: =IF($C8="","",$AP8*IF($AQ8="㎥",VLOOKUP('Scope 1'!AQ8,'[1]5-3. Unit Conversion'!$B$5:$J$13,3,FALSE)*VLOOKUP('Scope 1'!AB8,'[1]5-1. Fuel Density'!$B$6:$D$18,3,FALSE)*1000,IF($AQ8="kg",VLOOKUP('Scope 1'!AQ8,'[1]5-3. Unit Conversion'!$B$16:$G$21,3,FALSE),0))) -> 323390 | AS8: =IFERROR(IF($AB8="","",IF(VLOOKUP($AB8,'[1]5-1. Fuel Density'!$B$6:$G$19,6,0)="Use of other GHGs",0,IF($AB8="Industrial Wastes",$AR8*'[1]5-4. Calorific&Emission factor'!$R$75,$AR8*VLOOKUP($AB8,'[1]5-4. Calorific&Emission factor'!$P$9:$R$74,3,FALSE)))),0) -> 7035936.5 | AT8: =IF($AB8="","",IF(OR($AB8="Hydrofluorocarbons(HFCs)",$AB8="ETC"),$AR8*VLOOKUP($J8,'[1]5-4. Calorific&Emission factor'!$B$10:$D$14,3,0)/1000,IF(VLOOKUP($AB8,'[1]5-1. Fuel Density'!$B$6:$G$19,6,0)="Use of other GHGs",$AU8/1000,(($AU8*'[1]5-4. Calorific&Emission factor'!$D$7)+($AV8*'[1]5-4. Calorific&Emission factor'!$D$8)+($AW8*'[1]5-4. Calorific&Emission factor'!$D$9))/1000))) -> 1019.5213 | AU8: =IF($AB8="","",IF(VLOOKUP($AB8,'[1]5-1. Fuel Density'!$B$6:$G$19,6,0)="Use of other GHGs",$AR8*VLOOKUP($AB8,'[1]5-4. Calorific&Emission factor'!$O$9:$Y$74,5,FALSE)/1000000,$AS8*VLOOKUP($AB8,'[1]5-4. Calorific&Emission factor'!$P$9:$Y$74,4,FALSE)/1000000)) -> 1006138.9 | AV8: =IF($AB8="","",IF(VLOOKUP($AB8,'[1]5-1. Fuel Density'!$B$6:$G$19,6,0)="Use of other GHGs",0,$AS8*VLOOKUP($AB8,'[1]5-4. Calorific&Emission factor'!$P$9:$Y$74,6,FALSE)/1000000)) -> 211.0781 | AW8: =IF($AB8="","",IF(VLOOKUP($AB8,'[1]5-1. Fuel Density'!$B$6:$G$19,6,0)="Use of other GHGs",0,$AS8*VLOOKUP($AB8,'[1]5-4. Calorific&Emission factor'!$P$9:$Y$74,9,FALSE)/1000000)) -> 28.143746
B9: 4 | C9: PT. KAHOINDAH CITRAGARMENT | D9: KAHOINDAH CITRAGARMENT | E9: Forklift | F9: Fuel | G9: Mobile combustion fuels and vehicle | H9: to transport heavy weight item from one location to another location using forklift | I9: Biodiesel | J9: Biosolar (B30) | K9: 1.55 | L9: 0.13 | M9: 0.13 | N9: 0.14 | O9: 0.14 | P9: 0.12 | Q9: 0.12 | R9: 0.13 | S9: 0.14 | T9: 0.14 | U9: 0.12 | V9: 0.12 | W9: 0.12 | X9: ㎥ | Y9: 2022 | Z9: =VLOOKUP($E9,'[1]5-2. Emission Facility'!$B$7:$D$16,2,0) -> Forklift | AA9: =VLOOKUP($Z9,'[1]5-2. Emission Facility'!$C$7:$D$16,2,0) -> Mobile combustion | AB9: =IF($C9="","",IF(VLOOKUP($C9,'[1]1. General Facility Information'!$C$7:$E$13,3,0)="Korea",'Scope 1'!$I9,INDEX('[1]5-1. Fuel Density'!$B$6:$B$18,MATCH('Scope 1'!$I9,'[1]5-1. Fuel Density'!$C$6:$C$18,0)))) -> Biodiesel | AC9: =IF(OR($X9="㎥",$X9="kg"),$L9,"") -> 0.13 | AD9: =IF(OR($X9="㎥",$X9="kg"),M9,"") -> 0.13 | AE9: =IF(OR($X9="㎥",$X9="kg"),N9,"") -> 0.14 | AF9: =IF(OR($X9="㎥",$X9="kg"),O9,"") -> 0.14 | AG9: =IF(OR($X9="㎥",$X9="kg"),P9,"") -> 0.12 | AH9: =IF(OR($X9="㎥",$X9="kg"),Q9,"") -> 0.12 | AI9: =IF(OR($X9="㎥",$X9="kg"),R9,"") -> 0.13 | AJ9: =IF(OR($X9="㎥",$X9="kg"),S9,"") -> 0.14 | AK9: =IF(OR($X9="㎥",$X9="kg"),T9,"") -> 0.14 | ... AN9: =IF(OR($X9="㎥",$X9="kg"),W9,"") -> 0.12 | AO9: =IF(SUM(AC9:AN9)-AP9=0,"","X") | AP9: =IF(OR($X9="㎥",$X9="kg"),$K9,"") -> 1.55 | AQ9: =IF(OR($X9="㎥",$X9="kg"),$X9,"") -> ㎥ | AR9: =IF($C9="","",$AP9*IF($AQ9="㎥",VLOOKUP('Scope 1'!AQ9,'[1]5-3. Unit Conversion'!$B$5:$J$13,3,FALSE)*VLOOKUP('Scope 1'!AB9,'[1]5-1. Fuel Density'!$B$6:$D$18,3,FALSE)*1000,IF($AQ9="kg",VLOOKUP('Scope 1'!AQ9,'[1]5-3. Unit Conversion'!$B$16:$G$21,3,FALSE),0))) -> 1309.75 | AS9: =IFERROR(IF($AB9="","",IF(VLOOKUP($AB9,'[1]5-1. Fuel Density'!$B$6:$G$19,6,0)="Use of other GHGs",0,IF($AB9="Industrial Wastes",$AR9*'[1]5-4. Calorific&Emission factor'!$R$75,$AR9*VLOOKUP($AB9,'[1]5-4. Calorific&Emission factor'!$P$9:$R$74,3,FALSE)))),0) -> 35363.25 | AT9: =IF($AB9="","",IF(OR($AB9="Hydrofluorocarbons(HFCs)",$AB9="ETC"),$AR9*VLOOKUP($J9,'[1]5-4. Calorific&Emission factor'!$B$10:$D$14,3,0)/1000,IF(VLOOKUP($AB9,'[1]5-1. Fuel Density'!$B$6:$G$19,6,0)="Use of other GHGs",$AU9/1000,(($AU9*'[1]5-4. Calorific&Emission factor'!$D$7)+($AV9*'[1]5-4. Calorific&Emission factor'!$D$8)+($AW9*'[1]5-4. Calorific&Emission factor'!$D$9))/1000))) -> 2.512375 | AU9: =IF($AB9="","",IF(VLOOKUP($AB9,'[1]5-1. Fuel Density'!$B$6:$G$19,6,0)="Use of other GHGs",$AR9*VLOOKUP($AB9,'[1]5-4. Calorific&Emission factor'!$O$9:$Y$74,5,FALSE)/1000000,$AS9*VLOOKUP($AB9,'[1]5-4. Calorific&Emission factor'!$P$9:$Y$74,4,FALSE)/1000000)) -> 2503.7181 | AV9: =IF($AB9="","",IF(VLOOKUP($AB9,'[1]5-1. Fuel Density'!$B$6:$G$19,6,0)="Use of other GHGs",0,$AS9*VLOOKUP($AB9,'[1]5-4. Calorific&Emission factor'!$P$9:$Y$74,6,FALSE)/1000000)) -> 0.10608975 | AW9: =IF($AB9="","",IF(VLOOKUP($AB9,'[1]5-1. Fuel Density'!$B$6:$G$19,6,0)="Use of other GHGs",0,$AS9*VLOOKUP($AB9,'[1]5-4. Calorific&Emission factor'!$P$9:$Y$74,9,FALSE)/1000000)) -> 0.02121795
B10: 5 | C10: PT. KAHOINDAH CITRAGARMENT | D10: KAHOINDAH CITRAGARMENT | E10: Kitchen | F10: Fuel | G10: Stationary combustion fuels and equipment - Gaseous Fuel | H10: coocking food | I10: Liquefied Petroleum Gas (LPG) | J10: LPG 12 KG | K10: 312 | L10: 36 | M10: 36 | N10: 24 | O10: 24 | P10: 12 | Q10: 24 | R10: 36 | S10: 24 | T10: 12 | U10: 24 | V10: 48 | W10: 12 | X10: kg | Y10: 2022 | Z10: =VLOOKUP($E10,'[1]5-2. Emission Facility'!$B$7:$D$16,2,0) -> Kitchen | AA10: =VLOOKUP($Z10,'[1]5-2. Emission Facility'!$C$7:$D$16,2,0) -> Others | AB10: =IF($C10="","",IF(VLOOKUP($C10,'[1]1. General Facility Information'!$C$7:$E$13,3,0)="Korea",'Scope 1'!$I10,INDEX('[1]5-1. Fuel Density'!$B$6:$B$18,MATCH('Scope 1'!$I10,'[1]5-1. Fuel Density'!$C$6:$C$18,0)))) -> Liquefied Petroleum Gas (LPG) | AC10: =IF(OR($X10="㎥",$X10="kg"),$L10,"") -> 36 | AD10: =IF(OR($X10="㎥",$X10="kg"),M10,"") -> 36 | AE10: =IF(OR($X10="㎥",$X10="kg"),N10,"") -> 24 | AF10: =IF(OR($X10="㎥",$X10="kg"),O10,"") -> 24 | AG10: =IF(OR($X10="㎥",$X10="kg"),P10,"") -> 12 | AH10: =IF(OR($X10="㎥",$X10="kg"),Q10,"") -> 24 | AI10: =IF(OR($X10="㎥",$X10="kg"),R10,"") -> 36 | AJ10: =IF(OR($X10="㎥",$X10="kg"),S10,"") -> 24 | AK10: =IF(OR($X10="㎥",$X10="kg"),T10,"") -> 12 | ... AN10: =IF(OR($X10="㎥",$X10="kg"),W10,"") -> 12 | AO10: =IF(SUM(AC10:AN10)-AP10=0,"","X") | AP10: =IF(OR($X10="㎥",$X10="kg"),$K10,"") -> 312 | AQ10: =IF(OR($X10="㎥",$X10="kg"),$X10,"") -> kg | AR10: =IF($C10="","",$AP10*IF($AQ10="㎥",VLOOKUP('Scope 1'!AQ10,'[1]5-3. Unit Conversion'!$B$5:$J$13,3,FALSE)*VLOOKUP('Scope 1'!AB10,'[1]5-1. Fuel Density'!$B$6:$D$18,3,FALSE)*1000,IF($AQ10="kg",VLOOKUP('Scope 1'!AQ10,'[1]5-3. Unit Conversion'!$B$16:$G$21,3,FALSE),0))) -> 312 | AS10: =IFERROR(IF($AB10="","",IF(VLOOKUP($AB10,'[1]5-1. Fuel Density'!$B$6:$G$19,6,0)="Use of other GHGs",0,IF($AB10="Industrial Wastes",$AR10*'[1]5-4. Calorific&Emission factor'!$R$75,$AR10*VLOOKUP($AB10,'[1]5-4. Calorific&Emission factor'!$P$9:$R$74,3,FALSE)))),0) -> 14757.6 | AT10: =IF($AB10="","",IF(OR($AB10="Hydrofluorocarbons(HFCs)",$AB10="ETC"),$AR10*VLOOKUP($J10,'[1]5-4. Calorific&Emission factor'!$B$10:$D$14,3,0)/1000,IF(VLOOKUP($AB10,'[1]5-1. Fuel Density'!$B$6:$G$19,6,0)="Use of other GHGs",$AU10/1000,(($AU10*'[1]5-4. Calorific&Emission factor'!$D$7)+($AV10*'[1]5-4. Calorific&Emission factor'!$D$8)+($AW10*'[1]5-4. Calorific&Emission factor'!$D$9))/1000))) -> 0.9320059 | AU10: =IF($AB10="","",IF(VLOOKUP($AB10,'[1]5-1. Fuel Density'!$B$6:$G$19,6,0)="Use of other GHGs",$AR10*VLOOKUP($AB10,'[1]5-4. Calorific&Emission factor'!$O$9:$Y$74,5,FALSE)/1000000,$AS10*VLOOKUP($AB10,'[1]5-4. Calorific&Emission factor'!$P$9:$Y$74,4,FALSE)/1000000)) -> 931.20456 | AV10: =IF($AB10="","",IF(VLOOKUP($AB10,'[1]5-1. Fuel Density'!$B$6:$G$19,6,0)="Use of other GHGs",0,$AS10*VLOOKUP($AB10,'[1]5-4. Calorific&Emission factor'!$P$9:$Y$74,6,FALSE)/1000000)) -> 0.0147576 | AW10: =IF($AB10="","",IF(VLOOKUP($AB10,'[1]5-1. Fuel Density'!$B$6:$G$19,6,0)="Use of other GHGs",0,$AS10*VLOOKUP($AB10,'[1]5-4. Calorific&Emission factor'!$P$9:$Y$74,9,FALSE)/1000000)) -> 0.00147576
B11: 6 | C11: PT. YONGJIN JAVASUKA GARMENT | D11: PT. YONGJIN JAVASUKA GARMENT (1공장) | E11: Mess | F11: Fuel | G11: Stationary combustion | I11: Liquefied Petroleum Gas (LPG) | J11: LPG 12 KG | K11: 902.03 | L11: 72 | M11: 72 | N11: 72 | O11: 84 | P11: 72 | Q11: 85.15 | R11: 74.3 | S11: 86.3 | T11: 73.84 | U11: 74.3 | V11: 73.84 | W11: 62.3 | X11: kg | Y11: 2022 | Z11: =VLOOKUP($E11,'[1]5-2. Emission Facility'!$B$7:$D$16,2,0) -> Mess | AA11: =VLOOKUP($Z11,'[1]5-2. Emission Facility'!$C$7:$D$16,2,0) -> Others | AB11: =IF($C11="","",IF(VLOOKUP($C11,'[1]1. General Facility Information'!$C$7:$E$13,3,0)="Korea",'Scope 1'!$I11,INDEX('[1]5-1. Fuel Density'!$B$6:$B$18,MATCH('Scope 1'!$I11,'[1]5-1. Fuel Density'!$C$6:$C$18,0)))) -> Liquefied Petroleum Gas (LPG) | AC11: =IF(OR($X11="㎥",$X11="kg"),$L11,"") -> 72 | AD11: =IF(OR($X11="㎥",$X11="kg"),M11,"") -> 72 | AE11: =IF(OR($X11="㎥",$X11="kg"),N11,"") -> 72 | AF11: =IF(OR($X11="㎥",$X11="kg"),O11,"") -> 84 | AG11: =IF(OR($X11="㎥",$X11="kg"),P11,"") -> 72 | AH11: =IF(OR($X11="㎥",$X11="kg"),Q11,"") -> 85.15 | AI11: =IF(OR($X11="㎥",$X11="kg"),R11,"") -> 74.3 | AJ11: =IF(OR($X11="㎥",$X11="kg"),S11,"") -> 86.3 | AK11: =IF(OR($X11="㎥",$X11="kg"),T11,"") -> 73.84 | ... AN11: =IF(OR($X11="㎥",$X11="kg"),W11,"") -> 62.3 | AO11: =IF(SUM(AC11:AN11)-AP11=0,"","X") | AP11: =IF(OR($X11="㎥",$X11="kg"),$K11,"") -> 902.03 | AQ11: =IF(OR($X11="㎥",$X11="kg"),$X11,"") -> kg | AR11: =IF($C11="","",$AP11*IF($AQ11="㎥",VLOOKUP('Scope 1'!AQ11,'[1]5-3. Unit Conversion'!$B$5:$J$13,3,FALSE)*VLOOKUP('Scope 1'!AB11,'[1]5-1. Fuel Density'!$B$6:$D$18,3,FALSE)*1000,IF($AQ11="kg",VLOOKUP('Scope 1'!AQ11,'[1]5-3. Unit Conversion'!$B$16:$G$21,3,FALSE),0))) -> 902.03 | AS11: =IFERROR(IF($AB11="","",IF(VLOOKUP($AB11,'[1]5-1. Fuel Density'!$B$6:$G$19,6,0)="Use of other GHGs",0,IF($AB11="Industrial Wastes",$AR11*'[1]5-4. Calorific&Emission factor'!$R$75,$AR11*VLOOKUP($AB11,'[1]5-4. Calorific&Emission factor'!$P$9:$R$74,3,FALSE)))),0) -> 42666.019 | AT11: =IF($AB11="","",IF(OR($AB11="Hydrofluorocarbons(HFCs)",$AB11="ETC"),$AR11*VLOOKUP($J11,'[1]5-4. Calorific&Emission factor'!$B$10:$D$14,3,0)/1000,IF(VLOOKUP($AB11,'[1]5-1. Fuel Density'!$B$6:$G$19,6,0)="Use of other GHGs",$AU11/1000,(($AU11*'[1]5-4. Calorific&Emission factor'!$D$7)+($AV11*'[1]5-4. Calorific&Emission factor'!$D$8)+($AW11*'[1]5-4. Calorific&Emission factor'!$D$9))/1000))) -> 2.6945426 | AU11: =IF($AB11="","",IF(VLOOKUP($AB11,'[1]5-1. Fuel Density'!$B$6:$G$19,6,0)="Use of other GHGs",$AR11*VLOOKUP($AB11,'[1]5-4. Calorific&Emission factor'!$O$9:$Y$74,5,FALSE)/1000000,$AS11*VLOOKUP($AB11,'[1]5-4. Calorific&Emission factor'!$P$9:$Y$74,4,FALSE)/1000000)) -> 2692.2258 | AV11: =IF($AB11="","",IF(VLOOKUP($AB11,'[1]5-1. Fuel Density'!$B$6:$G$19,6,0)="Use of other GHGs",0,$AS11*VLOOKUP($AB11,'[1]5-4. Calorific&Emission factor'!$P$9:$Y$74,6,FALSE)/1000000)) -> 0.042666019 | AW11: =IF($AB11="","",IF(VLOOKUP($AB11,'[1]5-1. Fuel Density'!$B$6:$G$19,6,0)="Use of other GHGs",0,$AS11*VLOOKUP($AB11,'[1]5-4. Calorific&Emission factor'!$P$9:$Y$74,9,FALSE)/1000000)) -> 0.0042666019
B12: 7 | C12: PT. YONGJIN JAVASUKA GARMENT | D12: PT. YONGJIN JAVASUKA GARMENT (1공장) | E12: Generator | F12: Fuel | G12: Stationary combustion | I12: Gas / Diesel oil | J12: SOLAR | K12: 1.65 | L12: 0.1 | M12: 0.1 | N12: 0.15 | O12: 0.2 | P12: 0.1 | Q12: 0.1 | R12: 0.1 | S12: 0.1 | T12: 0.2 | U12: 0.05 | V12: 0.05 | W12: 0.4 | X12: ㎥ | Y12: 2022 | Z12: =VLOOKUP($E12,'[1]5-2. Emission Facility'!$B$7:$D$16,2,0) -> Generator | AA12: =VLOOKUP($Z12,'[1]5-2. Emission Facility'!$C$7:$D$16,2,0) -> Stationary Combustion | AB12: =IF($C12="","",IF(VLOOKUP($C12,'[1]1. General Facility Information'!$C$7:$E$13,3,0)="Korea",'Scope 1'!$I12,INDEX('[1]5-1. Fuel Density'!$B$6:$B$18,MATCH('Scope 1'!$I12,'[1]5-1. Fuel Density'!$C$6:$C$18,0)))) -> Gas / Diesel oil | AC12: =IF(OR($X12="㎥",$X12="kg"),$L12,"") -> 0.1 | AD12: =IF(OR($X12="㎥",$X12="kg"),M12,"") -> 0.1 | AE12: =IF(OR($X12="㎥",$X12="kg"),N12,"") -> 0.15 | AF12: =IF(OR($X12="㎥",$X12="kg"),O12,"") -> 0.2 | AG12: =IF(OR($X12="㎥",$X12="kg"),P12,"") -> 0.1 | AH12: =IF(OR($X12="㎥",$X12="kg"),Q12,"") -> 0.1 | AI12: =IF(OR($X12="㎥",$X12="kg"),R12,"") -> 0.1 | AJ12: =IF(OR($X12="㎥",$X12="kg"),S12,"") -> 0.1 | AK12: =IF(OR($X12="㎥",$X12="kg"),T12,"") -> 0.2 | ... AN12: =IF(OR($X12="㎥",$X12="kg"),W12,"") -> 0.4 | AO12: =IF(SUM(AC12:AN12)-AP12=0,"","X") | AP12: =IF(OR($X12="㎥",$X12="kg"),$K12,"") -> 1.65 | AQ12: =IF(OR($X12="㎥",$X12="kg"),$X12,"") -> ㎥ | AR12: =IF($C12="","",$AP12*IF($AQ12="㎥",VLOOKUP('Scope 1'!AQ12,'[1]5-3. Unit Conversion'!$B$5:$J$13,3,FALSE)*VLOOKUP('Scope 1'!AB12,'[1]5-1. Fuel Density'!$B$6:$D$18,3,FALSE)*1000,IF($AQ12="kg",VLOOKUP('Scope 1'!AQ12,'[1]5-3. Unit Conversion'!$B$16:$G$21,3,FALSE),0))) -> 1392.6 | AS12: =IFERROR(IF($AB12="","",IF(VLOOKUP($AB12,'[1]5-1. Fuel Density'!$B$6:$G$19,6,0)="Use of other GHGs",0,IF($AB12="Industrial Wastes",$AR12*'[1]5-4. Calorific&Emission factor'!$R$75,$AR12*VLOOKUP($AB12,'[1]5-4. Calorific&Emission factor'!$P$9:$R$74,3,FALSE)))),0) -> 59881.8 | AT12: =IF($AB12="","",IF(OR($AB12="Hydrofluorocarbons(HFCs)",$AB12="ETC"),$AR12*VLOOKUP($J12,'[1]5-4. Calorific&Emission factor'!$B$10:$D$14,3,0)/1000,IF(VLOOKUP($AB12,'[1]5-1. Fuel Density'!$B$6:$G$19,6,0)="Use of other GHGs",$AU12/1000,(($AU12*'[1]5-4. Calorific&Emission factor'!$D$7)+($AV12*'[1]5-4. Calorific&Emission factor'!$D$8)+($AW12*'[1]5-4. Calorific&Emission factor'!$D$9))/1000))) -> 4.4519004 | AU12: =IF($AB12="","",IF(VLOOKUP($AB12,'[1]5-1. Fuel Density'!$B$6:$G$19,6,0)="Use of other GHGs",$AR12*VLOOKUP($AB12,'[1]5-4. Calorific&Emission factor'!$O$9:$Y$74,5,FALSE)/1000000,$AS12*VLOOKUP($AB12,'[1]5-4. Calorific&Emission factor'!$P$9:$Y$74,4,FALSE)/1000000)) -> 4437.2414 | AV12: =IF($AB12="","",IF(VLOOKUP($AB12,'[1]5-1. Fuel Density'!$B$6:$G$19,6,0)="Use of other GHGs",0,$AS12*VLOOKUP($AB12,'[1]5-4. Calorific&Emission factor'!$P$9:$Y$74,6,FALSE)/1000000)) -> 0.1796454 | AW12: =IF($AB12="","",IF(VLOOKUP($AB12,'[1]5-1. Fuel Density'!$B$6:$G$19,6,0)="Use of other GHGs",0,$AS12*VLOOKUP($AB12,'[1]5-4. Calorific&Emission factor'!$P$9:$Y$74,9,FALSE)/1000000)) -> 0.03592908
B13: 8 | C13: PT. YONGJIN JAVASUKA GARMENT | D13: PT. YONGJIN JAVASUKA GARMENT (1공장) | E13: Boiler | F13: Fuel | G13: Stationary combustion | I13: Industrial Wastes | J13: FABRIC WASTE FROM CUTTING | K13: 364650 | L13: 40450 | M13: 36650 | N13: 29700 | O13: 28350 | P13: 21600 | Q13: 29700 | R13: 28350 | S13: 31050 | T13: 31050 | U13: 28350 | V13: 29700 | W13: 29700 | X13: kg | Y13: 2022 | Z13: =VLOOKUP($E13,'[1]5-2. Emission Facility'!$B$7:$D$16,2,0) -> Boiler | AA13: =VLOOKUP($Z13,'[1]5-2. Emission Facility'!$C$7:$D$16,2,0) -> Stationary Combustion | AB13: =IF($C13="","",IF(VLOOKUP($C13,'[1]1. General Facility Information'!$C$7:$E$13,3,0)="Korea",'Scope 1'!$I13,INDEX('[1]5-1. Fuel Density'!$B$6:$B$18,MATCH('Scope 1'!$I13,'[1]5-1. Fuel Density'!$C$6:$C$18,0)))) -> Industrial Wastes | AC13: =IF(OR($X13="㎥",$X13="kg"),$L13,"") -> 40450 | AD13: =IF(OR($X13="㎥",$X13="kg"),M13,"") -> 36650 | AE13: =IF(OR($X13="㎥",$X13="kg"),N13,"") -> 29700 | AF13: =IF(OR($X13="㎥",$X13="kg"),O13,"") -> 28350 | AG13: =IF(OR($X13="㎥",$X13="kg"),P13,"") -> 21600 | AH13: =IF(OR($X13="㎥",$X13="kg"),Q13,"") -> 29700 | AI13: =IF(OR($X13="㎥",$X13="kg"),R13,"") -> 28350 | AJ13: =IF(OR($X13="㎥",$X13="kg"),S13,"") -> 31050 | AK13: =IF(OR($X13="㎥",$X13="kg"),T13,"") -> 31050 | ... AN13: =IF(OR($X13="㎥",$X13="kg"),W13,"") -> 29700 | AO13: =IF(SUM(AC13:AN13)-AP13=0,"","X") | AP13: =IF(OR($X13="㎥",$X13="kg"),$K13,"") -> 364650 | AQ13: =IF(OR($X13="㎥",$X13="kg"),$X13,"") -> kg | AR13: =IF($C13="","",$AP13*IF($AQ13="㎥",VLOOKUP('Scope 1'!AQ13,'[1]5-3. Unit Conversion'!$B$5:$J$13,3,FALSE)*VLOOKUP('Scope 1'!AB13,'[1]5-1. Fuel Density'!$B$6:$D$18,3,FALSE)*1000,IF($AQ13="kg",VLOOKUP('Scope 1'!AQ13,'[1]5-3. Unit Conversion'!$B$16:$G$21,3,FALSE),0))) -> 364650 | AS13: =IFERROR(IF($AB13="","",IF(VLOOKUP($AB13,'[1]5-1. Fuel Density'!$B$6:$G$19,6,0)="Use of other GHGs",0,IF($AB13="Industrial Wastes",$AR13*'[1]5-4. Calorific&Emission factor'!$R$75,$AR13*VLOOKUP($AB13,'[1]5-4. Calorific&Emission factor'!$P$9:$R$74,3,FALSE)))),0) -> 7933622.8 | AT13: =IF($AB13="","",IF(OR($AB13="Hydrofluorocarbons(HFCs)",$AB13="ETC"),$AR13*VLOOKUP($J13,'[1]5-4. Calorific&Emission factor'!$B$10:$D$14,3,0)/1000,IF(VLOOKUP($AB13,'[1]5-1. Fuel Density'!$B$6:$G$19,6,0)="Use of other GHGs",$AU13/1000,(($AU13*'[1]5-4. Calorific&Emission factor'!$D$7)+($AV13*'[1]5-4. Calorific&Emission factor'!$D$8)+($AW13*'[1]5-4. Calorific&Emission factor'!$D$9))/1000))) -> 1149.5978 | AU13: =IF($AB13="","",IF(VLOOKUP($AB13,'[1]5-1. Fuel Density'!$B$6:$G$19,6,0)="Use of other GHGs",$AR13*VLOOKUP($AB13,'[1]5-4. Calorific&Emission factor'!$O$9:$Y$74,5,FALSE)/1000000,$AS13*VLOOKUP($AB13,'[1]5-4. Calorific&Emission factor'!$P$9:$Y$74,4,FALSE)/1000000)) -> 1134508.1 | AV13: =IF($AB13="","",IF(VLOOKUP($AB13,'[1]5-1. Fuel Density'!$B$6:$G$19,6,0)="Use of other GHGs",0,$AS13*VLOOKUP($AB13,'[1]5-4. Calorific&Emission factor'!$P$9:$Y$74,6,FALSE)/1000000)) -> 238.00868 | AW13: =IF($AB13="","",IF(VLOOKUP($AB13,'[1]5-1. Fuel Density'!$B$6:$G$19,6,0)="Use of other GHGs",0,$AS13*VLOOKUP($AB13,'[1]5-4. Calorific&Emission factor'!$P$9:$Y$74,9,FALSE)/1000000)) -> 31.734491
B14: 9 | C14: PT. YONGJIN JAVASUKA GARMENT | D14: PT. YONGJIN JAVASUKA GARMENT (1공장) | E14: AC | F14: RawMaterial | G14: Others | I14: Hydrofluorocarbons(HFCs) | J14: HFC-410A | K14: 33.9 | P14: 11.3 | T14: 11.3 | V14: 11.3 | X14: kg | Y14: 2022 | Z14: =VLOOKUP($E14,'[1]5-2. Emission Facility'!$B$7:$D$16,2,0) -> AC | AA14: =VLOOKUP($Z14,'[1]5-2. Emission Facility'!$C$7:$D$16,2,0) -> Process Emissions | AB14: =IF($C14="","",IF(VLOOKUP($C14,'[1]1. General Facility Information'!$C$7:$E$13,3,0)="Korea",'Scope 1'!$I14,INDEX('[1]5-1. Fuel Density'!$B$6:$B$18,MATCH('Scope 1'!$I14,'[1]5-1. Fuel Density'!$C$6:$C$18,0)))) -> Hydrofluorocarbons(HFCs) | AC14: =IF(OR($X14="㎥",$X14="kg"),$L14,"") -> 0 | AD14: =IF(OR($X14="㎥",$X14="kg"),M14,"") -> 0 | AE14: =IF(OR($X14="㎥",$X14="kg"),N14,"") -> 0 | AF14: =IF(OR($X14="㎥",$X14="kg"),O14,"") -> 0 | AG14: =IF(OR($X14="㎥",$X14="kg"),P14,"") -> 11.3 | AH14: =IF(OR($X14="㎥",$X14="kg"),Q14,"") -> 0 | AI14: =IF(OR($X14="㎥",$X14="kg"),R14,"") -> 0 | AJ14: =IF(OR($X14="㎥",$X14="kg"),S14,"") -> 0 | AK14: =IF(OR($X14="㎥",$X14="kg"),T14,"") -> 11.3 | ... AN14: =IF(OR($X14="㎥",$X14="kg"),W14,"") -> 0 | AO14: =IF(SUM(AC14:AN14)-AP14=0,"","X") | AP14: =IF(OR($X14="㎥",$X14="kg"),$K14,"") -> 33.9 | AQ14: =IF(OR($X14="㎥",$X14="kg"),$X14,"") -> kg | AR14: =IF($C14="","",$AP14*IF($AQ14="㎥",VLOOKUP('Scope 1'!AQ14,'[1]5-3. Unit Conversion'!$B$5:$J$13,3,FALSE)*VLOOKUP('Scope 1'!AB14,'[1]5-1. Fuel Density'!$B$6:$D$18,3,FALSE)*1000,IF($AQ14="kg",VLOOKUP('Scope 1'!AQ14,'[1]5-3. Unit Conversion'!$B$16:$G$21,3,FALSE),0))) -> 33.9 | AS14: =IFERROR(IF($AB14="","",IF(VLOOKUP($AB14,'[1]5-1. Fuel Density'!$B$6:$G$19,6,0)="Use of other GHGs",0,IF($AB14="Industrial Wastes",$AR14*'[1]5-4. Calorific&Emission factor'!$R$75,$AR14*VLOOKUP($AB14,'[1]5-4. Calorific&Emission factor'!$P$9:$R$74,3,FALSE)))),0) -> 0 | AT14: =IF($AB14="","",IF(OR($AB14="Hydrofluorocarbons(HFCs)",$AB14="ETC"),$AR14*VLOOKUP($J14,'[1]5-4. Calorific&Emission factor'!$B$10:$D$14,3,0)/1000,IF(VLOOKUP($AB14,'[1]5-1. Fuel Density'!$B$6:$G$19,6,0)="Use of other GHGs",$AU14/1000,(($AU14*'[1]5-4. Calorific&Emission factor'!$D$7)+($AV14*'[1]5-4. Calorific&Emission factor'!$D$8)+($AW14*'[1]5-4. Calorific&Emission factor'!$D$9))/1000))) -> 76.46145 | AU14: =IF($AB14="","",IF(VLOOKUP($AB14,'[1]5-1. Fuel Density'!$B$6:$G$19,6,0)="Use of other GHGs",$AR14*VLOOKUP($AB14,'[1]5-4. Calorific&Emission factor'!$O$9:$Y$74,5,FALSE)/1000000,$AS14*VLOOKUP($AB14,'[1]5-4. Calorific&Emission factor'!$P$9:$Y$74,4,FALSE)/1000000)) -> 0 | AV14: =IF($AB14="","",IF(VLOOKUP($AB14,'[1]5-1. Fuel Density'!$B$6:$G$19,6,0)="Use of other GHGs",0,$AS14*VLOOKUP($AB14,'[1]5-4. Calorific&Emission factor'!$P$9:$Y$74,6,FALSE)/1000000)) -> 0 | AW14: =IF($AB14="","",IF(VLOOKUP($AB14,'[1]5-1. Fuel Density'!$B$6:$G$19,6,0)="Use of other GHGs",0,$AS14*VLOOKUP($AB14,'[1]5-4. Calorific&Emission factor'!$P$9:$Y$74,9,FALSE)/1000000)) -> 0
B15: 10 | C15: PT. YONGJIN JAVASUKA GARMENT | D15: PT. YONGJIN JAVASUKA GARMENT (1공장) | E15: AC | F15: RawMaterial | G15: Others | I15: ETC | J15: HCFC-22 | K15: 40.8 | S15: 13.6 | V15: 27.2 | X15: kg | Y15: 2022 | Z15: =VLOOKUP($E15,'[1]5-2. Emission Facility'!$B$7:$D$16,2,0) -> AC | AA15: =VLOOKUP($Z15,'[1]5-2. Emission Facility'!$C$7:$D$16,2,0) -> Process Emissions | AB15: =IF($C15="","",IF(VLOOKUP($C15,'[1]1. General Facility Information'!$C$7:$E$13,3,0)="Korea",'Scope 1'!$I15,INDEX('[1]5-1. Fuel Density'!$B$6:$B$18,MATCH('Scope 1'!$I15,'[1]5-1. Fuel Density'!$C$6:$C$18,0)))) -> Hydrofluorocarbons(HFCs) | AC15: =IF(OR($X15="㎥",$X15="kg"),$L15,"") -> 0 | AD15: =IF(OR($X15="㎥",$X15="kg"),M15,"") -> 0 | AE15: =IF(OR($X15="㎥",$X15="kg"),N15,"") -> 0 | AF15: =IF(OR($X15="㎥",$X15="kg"),O15,"") -> 0 | AG15: =IF(OR($X15="㎥",$X15="kg"),P15,"") -> 0 | AH15: =IF(OR($X15="㎥",$X15="kg"),Q15,"") -> 0 | AI15: =IF(OR($X15="㎥",$X15="kg"),R15,"") -> 0 | AJ15: =IF(OR($X15="㎥",$X15="kg"),S15,"") -> 13.6 | AK15: =IF(OR($X15="㎥",$X15="kg"),T15,"") -> 0 | ... AN15: =IF(OR($X15="㎥",$X15="kg"),W15,"") -> 0 | AO15: =IF(SUM(AC15:AN15)-AP15=0,"","X") | AP15: =IF(OR($X15="㎥",$X15="kg"),$K15,"") -> 40.8 | AQ15: =IF(OR($X15="㎥",$X15="kg"),$X15,"") -> kg | AR15: =IF($C15="","",$AP15*IF($AQ15="㎥",VLOOKUP('Scope 1'!AQ15,'[1]5-3. Unit Conversion'!$B$5:$J$13,3,FALSE)*VLOOKUP('Scope 1'!AB15,'[1]5-1. Fuel Density'!$B$6:$D$18,3,FALSE)*1000,IF($AQ15="kg",VLOOKUP('Scope 1'!AQ15,'[1]5-3. Unit Conversion'!$B$16:$G$21,3,FALSE),0))) -> 40.8 | AS15: =IFERROR(IF($AB15="","",IF(VLOOKUP($AB15,'[1]5-1. Fuel Density'!$B$6:$G$19,6,0)="Use of other GHGs",0,IF($AB15="Industrial Wastes",$AR15*'[1]5-4. Calorific&Emission factor'!$R$75,$AR15*VLOOKUP($AB15,'[1]5-4. Calorific&Emission factor'!$P$9:$R$74,3,FALSE)))),0) -> 0 | AT15: =IF($AB15="","",IF(OR($AB15="Hydrofluorocarbons(HFCs)",$AB15="ETC"),$AR15*VLOOKUP($J15,'[1]5-4. Calorific&Emission factor'!$B$10:$D$14,3,0)/1000,IF(VLOOKUP($AB15,'[1]5-1. Fuel Density'!$B$6:$G$19,6,0)="Use of other GHGs",$AU15/1000,(($AU15*'[1]5-4. Calorific&Emission factor'!$D$7)+($AV15*'[1]5-4. Calorific&Emission factor'!$D$8)+($AW15*'[1]5-4. Calorific&Emission factor'!$D$9))/1000))) -> 79.968 | AU15: =IF($AB15="","",IF(VLOOKUP($AB15,'[1]5-1. Fuel Density'!$B$6:$G$19,6,0)="Use of other GHGs",$AR15*VLOOKUP($AB15,'[1]5-4. Calorific&Emission factor'!$O$9:$Y$74,5,FALSE)/1000000,$AS15*VLOOKUP($AB15,'[1]5-4. Calorific&Emission factor'!$P$9:$Y$74,4,FALSE)/1000000)) -> 0 | AV15: =IF($AB15="","",IF(VLOOKUP($AB15,'[1]5-1. Fuel Density'!$B$6:$G$19,6,0)="Use of other GHGs",0,$AS15*VLOOKUP($AB15,'[1]5-4. Calorific&Emission factor'!$P$9:$Y$74,6,FALSE)/1000000)) -> 0 | AW15: =IF($AB15="","",IF(VLOOKUP($AB15,'[1]5-1. Fuel Density'!$B$6:$G$19,6,0)="Use of other GHGs",0,$AS15*VLOOKUP($AB15,'[1]5-4. Calorific&Emission factor'!$P$9:$Y$74,9,FALSE)/1000000)) -> 0
B16: 11 | C16: PT. YONGJIN JAVASUKA GARMENT | D16: PT. YONGJIN JAVASUKA GARMENT (1공장) | E16: Car | F16: Fuel | G16: Mobile combustion | I16: Automotive gasoline/diesel oil | J16: DIESEL OIL | K16: 49.929249 | L16: 5.46506 | M16: 4.499161 | N16: 5.1348 | O16: 5.58748 | P16: 5.0319 | Q16: 5.3198 | R16: 5.954588 | S16: 5.77436 | T16: 1.9721 | U16: 1.715 | V16: 1.657 | W16: 1.818 | X16: ㎥ | Y16: 2022 | Z16: =VLOOKUP($E16,'[1]5-2. Emission Facility'!$B$7:$D$16,2,0) -> Vehicle | AA16: =VLOOKUP($Z16,'[1]5-2. Emission Facility'!$C$7:$D$16,2,0) -> Mobile combustion | AB16: =IF($C16="","",IF(VLOOKUP($C16,'[1]1. General Facility Information'!$C$7:$E$13,3,0)="Korea",'Scope 1'!$I16,INDEX('[1]5-1. Fuel Density'!$B$6:$B$18,MATCH('Scope 1'!$I16,'[1]5-1. Fuel Density'!$C$6:$C$18,0)))) -> Automotive gasoline (petrol) | AC16: =IF(OR($X16="㎥",$X16="kg"),$L16,"") -> 5.46506 | AD16: =IF(OR($X16="㎥",$X16="kg"),M16,"") -> 4.499161 | AE16: =IF(OR($X16="㎥",$X16="kg"),N16,"") -> 5.1348 | AF16: =IF(OR($X16="㎥",$X16="kg"),O16,"") -> 5.58748 | AG16: =IF(OR($X16="㎥",$X16="kg"),P16,"") -> 5.0319 | AH16: =IF(OR($X16="㎥",$X16="kg"),Q16,"") -> 5.3198 | AI16: =IF(OR($X16="㎥",$X16="kg"),R16,"") -> 5.954588 | AJ16: =IF(OR($X16="㎥",$X16="kg"),S16,"") -> 5.77436 | AK16: =IF(OR($X16="㎥",$X16="kg"),T16,"") -> 1.9721 | ... AN16: =IF(OR($X16="㎥",$X16="kg"),W16,"") -> 1.818 | AO16: =IF(SUM(AC16:AN16)-AP16=0,"","X") | AP16: =IF(OR($X16="㎥",$X16="kg"),$K16,"") -> 49.929249 | AQ16: =IF(OR($X16="㎥",$X16="kg"),$X16,"") -> ㎥ | AR16: =IF($C16="","",$AP16*IF($AQ16="㎥",VLOOKUP('Scope 1'!AQ16,'[1]5-3. Unit Conversion'!$B$5:$J$13,3,FALSE)*VLOOKUP('Scope 1'!AB16,'[1]5-1. Fuel Density'!$B$6:$D$18,3,FALSE)*1000,IF($AQ16="kg",VLOOKUP('Scope 1'!AQ16,'[1]5-3. Unit Conversion'!$B$16:$G$21,3,FALSE),0))) -> 36997.574 | AS16: =IFERROR(IF($AB16="","",IF(VLOOKUP($AB16,'[1]5-1. Fuel Density'!$B$6:$G$19,6,0)="Use of other GHGs",0,IF($AB16="Industrial Wastes",$AR16*'[1]5-4. Calorific&Emission factor'!$R$75,$AR16*VLOOKUP($AB16,'[1]5-4. Calorific&Emission factor'!$P$9:$R$74,3,FALSE)))),0) -> 1638992.5 | AT16: =IF($AB16="","",IF(OR($AB16="Hydrofluorocarbons(HFCs)",$AB16="ETC"),$AR16*VLOOKUP($J16,'[1]5-4. Calorific&Emission factor'!$B$10:$D$14,3,0)/1000,IF(VLOOKUP($AB16,'[1]5-1. Fuel Density'!$B$6:$G$19,6,0)="Use of other GHGs",$AU16/1000,(($AU16*'[1]5-4. Calorific&Emission factor'!$D$7)+($AV16*'[1]5-4. Calorific&Emission factor'!$D$8)+($AW16*'[1]5-4. Calorific&Emission factor'!$D$9))/1000))) -> 113.98341 | AU16: =IF($AB16="","",IF(VLOOKUP($AB16,'[1]5-1. Fuel Density'!$B$6:$G$19,6,0)="Use of other GHGs",$AR16*VLOOKUP($AB16,'[1]5-4. Calorific&Emission factor'!$O$9:$Y$74,5,FALSE)/1000000,$AS16*VLOOKUP($AB16,'[1]5-4. Calorific&Emission factor'!$P$9:$Y$74,4,FALSE)/1000000)) -> 113582.18 | AV16: =IF($AB16="","",IF(VLOOKUP($AB16,'[1]5-1. Fuel Density'!$B$6:$G$19,6,0)="Use of other GHGs",0,$AS16*VLOOKUP($AB16,'[1]5-4. Calorific&Emission factor'!$P$9:$Y$74,6,FALSE)/1000000)) -> 4.9169775 | AW16: =IF($AB16="","",IF(VLOOKUP($AB16,'[1]5-1. Fuel Density'!$B$6:$G$19,6,0)="Use of other GHGs",0,$AS16*VLOOKUP($AB16,'[1]5-4. Calorific&Emission factor'!$P$9:$Y$74,9,FALSE)/1000000)) -> 0.9833955
B17: 12 | C17: PT. YONGJIN JAVASUKA GARMENT | D17: PT. YONGJIN JAVASUKA GARMENT (1공장) | E17: Car | F17: Fuel | G17: Mobile combustion | I17: Automotive gasoline/diesel oil | J17: GASOLINE | K17: 22.31647 | L17: 0.037 | R17: 0.544 | S17: 0.723 | T17: 4.67024 | U17: 6.3399 | V17: 4.91562 | W17: 5.08671 | X17: ㎥ | Y17: 2022 | Z17: =VLOOKUP($E17,'[1]5-2. Emission Facility'!$B$7:$D$16,2,0) -> Vehicle | AA17: =VLOOKUP($Z17,'[1]5-2. Emission Facility'!$C$7:$D$16,2,0) -> Mobile combustion | AB17: =IF($C17="","",IF(VLOOKUP($C17,'[1]1. General Facility Information'!$C$7:$E$13,3,0)="Korea",'Scope 1'!$I17,INDEX('[1]5-1. Fuel Density'!$B$6:$B$18,MATCH('Scope 1'!$I17,'[1]5-1. Fuel Density'!$C$6:$C$18,0)))) -> Automotive gasoline (petrol) | AC17: =IF(OR($X17="㎥",$X17="kg"),$L17,"") -> 0.037 | AD17: =IF(OR($X17="㎥",$X17="kg"),M17,"") -> 0 | AE17: =IF(OR($X17="㎥",$X17="kg"),N17,"") -> 0 | AF17: =IF(OR($X17="㎥",$X17="kg"),O17,"") -> 0 | AG17: =IF(OR($X17="㎥",$X17="kg"),P17,"") -> 0 | AH17: =IF(OR($X17="㎥",$X17="kg"),Q17,"") -> 0 | AI17: =IF(OR($X17="㎥",$X17="kg"),R17,"") -> 0.544 | AJ17: =IF(OR($X17="㎥",$X17="kg"),S17,"") -> 0.723 | AK17: =IF(OR($X17="㎥",$X17="kg"),T17,"") -> 4.67024 | ... AN17: =IF(OR($X17="㎥",$X17="kg"),W17,"") -> 5.08671 | AO17: =IF(SUM(AC17:AN17)-AP17=0,"","X") | AP17: =IF(OR($X17="㎥",$X17="kg"),$K17,"") -> 22.31647 | AQ17: =IF(OR($X17="㎥",$X17="kg"),$X17,"") -> ㎥ | AR17: =IF($C17="","",$AP17*IF($AQ17="㎥",VLOOKUP('Scope 1'!AQ17,'[1]5-3. Unit Conversion'!$B$5:$J$13,3,FALSE)*VLOOKUP('Scope 1'!AB17,'[1]5-1. Fuel Density'!$B$6:$D$18,3,FALSE)*1000,IF($AQ17="kg",VLOOKUP('Scope 1'!AQ17,'[1]5-3. Unit Conversion'!$B$16:$G$21,3,FALSE),0))) -> 16536.504 | AS17: =IFERROR(IF($AB17="","",IF(VLOOKUP($AB17,'[1]5-1. Fuel Density'!$B$6:$G$19,6,0)="Use of other GHGs",0,IF($AB17="Industrial Wastes",$AR17*'[1]5-4. Calorific&Emission factor'!$R$75,$AR17*VLOOKUP($AB17,'[1]5-4. Calorific&Emission factor'!$P$9:$R$74,3,FALSE)))),0) -> 732567.14 | AT17: =IF($AB17="","",IF(OR($AB17="Hydrofluorocarbons(HFCs)",$AB17="ETC"),$AR17*VLOOKUP($J17,'[1]5-4. Calorific&Emission factor'!$B$10:$D$14,3,0)/1000,IF(VLOOKUP($AB17,'[1]5-1. Fuel Density'!$B$6:$G$19,6,0)="Use of other GHGs",$AU17/1000,(($AU17*'[1]5-4. Calorific&Emission factor'!$D$7)+($AV17*'[1]5-4. Calorific&Emission factor'!$D$8)+($AW17*'[1]5-4. Calorific&Emission factor'!$D$9))/1000))) -> 50.946235 | AU17: =IF($AB17="","",IF(VLOOKUP($AB17,'[1]5-1. Fuel Density'!$B$6:$G$19,6,0)="Use of other GHGs",$AR17*VLOOKUP($AB17,'[1]5-4. Calorific&Emission factor'!$O$9:$Y$74,5,FALSE)/1000000,$AS17*VLOOKUP($AB17,'[1]5-4. Calorific&Emission factor'!$P$9:$Y$74,4,FALSE)/1000000)) -> 50766.903 | AV17: =IF($AB17="","",IF(VLOOKUP($AB17,'[1]5-1. Fuel Density'!$B$6:$G$19,6,0)="Use of other GHGs",0,$AS17*VLOOKUP($AB17,'[1]5-4. Calorific&Emission factor'!$P$9:$Y$74,6,FALSE)/1000000)) -> 2.1977014 | AW17: =IF($AB17="","",IF(VLOOKUP($AB17,'[1]5-1. Fuel Density'!$B$6:$G$19,6,0)="Use of other GHGs",0,$AS17*VLOOKUP($AB17,'[1]5-4. Calorific&Emission factor'!$P$9:$Y$74,9,FALSE)/1000000)) -> 0.43954028
B18: 13 | C18: PT. YONGJIN JAVASUKA GARMENT | D18: PT. YONGJIN JAVASUKA GARMENT (2,3공장) | E18: Mess | F18: Fuel | G18: Stationary combustion | I18: Liquefied Petroleum Gas (LPG) | J18: LPG 12 KG & CAN 230 GR | K18: 1665.78 | L18: 144 | M18: 120 | N18: 144 | O18: 122.46 | P18: 122.46 | Q18: 146.96 | R18: 148.44 | S18: 148.44 | T18: 123.7 | U18: 148.44 | V18: 148.44 | W18: 148.44 | X18: kg | Y18: 2022 | Z18: =VLOOKUP($E18,'[1]5-2. Emission Facility'!$B$7:$D$16,2,0) -> Mess | AA18: =VLOOKUP($Z18,'[1]5-2. Emission Facility'!$C$7:$D$16,2,0) -> Others | AB18: =IF($C18="","",IF(VLOOKUP($C18,'[1]1. General Facility Information'!$C$7:$E$13,3,0)="Korea",'Scope 1'!$I18,INDEX('[1]5-1. Fuel Density'!$B$6:$B$18,MATCH('Scope 1'!$I18,'[1]5-1. Fuel Density'!$C$6:$C$18,0)))) -> Liquefied Petroleum Gas (LPG) | AC18: =IF(OR($X18="㎥",$X18="kg"),$L18,"") -> 144 | AD18: =IF(OR($X18="㎥",$X18="kg"),M18,"") -> 120 | AE18: =IF(OR($X18="㎥",$X18="kg"),N18,"") -> 144 | AF18: =IF(OR($X18="㎥",$X18="kg"),O18,"") -> 122.46 | AG18: =IF(OR($X18="㎥",$X18="kg"),P18,"") -> 122.46 | AH18: =IF(OR($X18="㎥",$X18="kg"),Q18,"") -> 146.96 | AI18: =IF(OR($X18="㎥",$X18="kg"),R18,"") -> 148.44 | AJ18: =IF(OR($X18="㎥",$X18="kg"),S18,"") -> 148.44 | AK18: =IF(OR($X18="㎥",$X18="kg"),T18,"") -> 123.7 | ... AN18: =IF(OR($X18="㎥",$X18="kg"),W18,"") -> 148.44 | AO18: =IF(SUM(AC18:AN18)-AP18=0,"","X") | AP18: =IF(OR($X18="㎥",$X18="kg"),$K18,"") -> 1665.78 | AQ18: =IF(OR($X18="㎥",$X18="kg"),$X18,"") -> kg | AR18: =IF($C18="","",$AP18*IF($AQ18="㎥",VLOOKUP('Scope 1'!AQ18,'[1]5-3. Unit Conversion'!$B$5:$J$13,3,FALSE)*VLOOKUP('Scope 1'!AB18,'[1]5-1. Fuel Density'!$B$6:$D$18,3,FALSE)*1000,IF($AQ18="kg",VLOOKUP('Scope 1'!AQ18,'[1]5-3. Unit Conversion'!$B$16:$G$21,3,FALSE),0))) -> 1665.78 | AS18: =IFERROR(IF($AB18="","",IF(VLOOKUP($AB18,'[1]5-1. Fuel Density'!$B$6:$G$19,6,0)="Use of other GHGs",0,IF($AB18="Industrial Wastes",$AR18*'[1]5-4. Calorific&Emission factor'!$R$75,$AR18*VLOOKUP($AB18,'[1]5-4. Calorific&Emission factor'!$P$9:$R$74,3,FALSE)))),0) -> 78791.394 | AT18: =IF($AB18="","",IF(OR($AB18="Hydrofluorocarbons(HFCs)",$AB18="ETC"),$AR18*VLOOKUP($J18,'[1]5-4. Calorific&Emission factor'!$B$10:$D$14,3,0)/1000,IF(VLOOKUP($AB18,'[1]5-1. Fuel Density'!$B$6:$G$19,6,0)="Use of other GHGs",$AU18/1000,(($AU18*'[1]5-4. Calorific&Emission factor'!$D$7)+($AV18*'[1]5-4. Calorific&Emission factor'!$D$8)+($AW18*'[1]5-4. Calorific&Emission factor'!$D$9))/1000))) -> 4.9760153 | AU18: =IF($AB18="","",IF(VLOOKUP($AB18,'[1]5-1. Fuel Density'!$B$6:$G$19,6,0)="Use of other GHGs",$AR18*VLOOKUP($AB18,'[1]5-4. Calorific&Emission factor'!$O$9:$Y$74,5,FALSE)/1000000,$AS18*VLOOKUP($AB18,'[1]5-4. Calorific&Emission factor'!$P$9:$Y$74,4,FALSE)/1000000)) -> 4971.737 | AV18: =IF($AB18="","",IF(VLOOKUP($AB18,'[1]5-1. Fuel Density'!$B$6:$G$19,6,0)="Use of other GHGs",0,$AS18*VLOOKUP($AB18,'[1]5-4. Calorific&Emission factor'!$P$9:$Y$74,6,FALSE)/1000000)) -> 0.078791394 | AW18: =IF($AB18="","",IF(VLOOKUP($AB18,'[1]5-1. Fuel Density'!$B$6:$G$19,6,0)="Use of other GHGs",0,$AS18*VLOOKUP($AB18,'[1]5-4. Calorific&Emission factor'!$P$9:$Y$74,9,FALSE)/1000000)) -> 0.0078791394
B19: 14 | C19: PT. YONGJIN JAVASUKA GARMENT | D19: PT. YONGJIN JAVASUKA GARMENT (2,3공장) | E19: Generator | F19: Fuel | G19: Stationary combustion | I19: Gas / Diesel oil | J19: SOLAR/DIESEL OIL | K19: 17.454 | L19: 2.5 | M19: 1 | N19: 1 | O19: 1.3 | P19: 1.25 | Q19: 1 | R19: 1 | S19: 1.25 | T19: 1 | U19: 3.65 | V19: 1 | W19: 1.504 | X19: ㎥ | Y19: 2022 | Z19: =VLOOKUP($E19,'[1]5-2. Emission Facility'!$B$7:$D$16,2,0) -> Generator | AA19: =VLOOKUP($Z19,'[1]5-2. Emission Facility'!$C$7:$D$16,2,0) -> Stationary Combustion | AB19: =IF($C19="","",IF(VLOOKUP($C19,'[1]1. General Facility Information'!$C$7:$E$13,3,0)="Korea",'Scope 1'!$I19,INDEX('[1]5-1. Fuel Density'!$B$6:$B$18,MATCH('Scope 1'!$I19,'[1]5-1. Fuel Density'!$C$6:$C$18,0)))) -> Gas / Diesel oil | AC19: =IF(OR($X19="㎥",$X19="kg"),$L19,"") -> 2.5 | AD19: =IF(OR($X19="㎥",$X19="kg"),M19,"") -> 1 | AE19: =IF(OR($X19="㎥",$X19="kg"),N19,"") -> 1 | AF19: =IF(OR($X19="㎥",$X19="kg"),O19,"") -> 1.3 | AG19: =IF(OR($X19="㎥",$X19="kg"),P19,"") -> 1.25 | AH19: =IF(OR($X19="㎥",$X19="kg"),Q19,"") -> 1 | AI19: =IF(OR($X19="㎥",$X19="kg"),R19,"") -> 1 | AJ19: =IF(OR($X19="㎥",$X19="kg"),S19,"") -> 1.25 | AK19: =IF(OR($X19="㎥",$X19="kg"),T19,"") -> 1 | ... AN19: =IF(OR($X19="㎥",$X19="kg"),W19,"") -> 1.504 | AO19: =IF(SUM(AC19:AN19)-AP19=0,"","X") | AP19: =IF(OR($X19="㎥",$X19="kg"),$K19,"") -> 17.454 | AQ19: =IF(OR($X19="㎥",$X19="kg"),$X19,"") -> ㎥ | AR19: =IF($C19="","",$AP19*IF($AQ19="㎥",VLOOKUP('Scope 1'!AQ19,'[1]5-3. Unit Conversion'!$B$5:$J$13,3,FALSE)*VLOOKUP('Scope 1'!AB19,'[1]5-1. Fuel Density'!$B$6:$D$18,3,FALSE)*1000,IF($AQ19="kg",VLOOKUP('Scope 1'!AQ19,'[1]5-3. Unit Conversion'!$B$16:$G$21,3,FALSE),0))) -> 14731.176 | AS19: =IFERROR(IF($AB19="","",IF(VLOOKUP($AB19,'[1]5-1. Fuel Density'!$B$6:$G$19,6,0)="Use of other GHGs",0,IF($AB19="Industrial Wastes",$AR19*'[1]5-4. Calorific&Emission factor'!$R$75,$AR19*VLOOKUP($AB19,'[1]5-4. Calorific&Emission factor'!$P$9:$R$74,3,FALSE)))),0) -> 633440.57 | AT19: =IF($AB19="","",IF(OR($AB19="Hydrofluorocarbons(HFCs)",$AB19="ETC"),$AR19*VLOOKUP($J19,'[1]5-4. Calorific&Emission factor'!$B$10:$D$14,3,0)/1000,IF(VLOOKUP($AB19,'[1]5-1. Fuel Density'!$B$6:$G$19,6,0)="Use of other GHGs",$AU19/1000,(($AU19*'[1]5-4. Calorific&Emission factor'!$D$7)+($AV19*'[1]5-4. Calorific&Emission factor'!$D$8)+($AW19*'[1]5-4. Calorific&Emission factor'!$D$9))/1000))) -> 47.093012 | AU19: =IF($AB19="","",IF(VLOOKUP($AB19,'[1]5-1. Fuel Density'!$B$6:$G$19,6,0)="Use of other GHGs",$AR19*VLOOKUP($AB19,'[1]5-4. Calorific&Emission factor'!$O$9:$Y$74,5,FALSE)/1000000,$AS19*VLOOKUP($AB19,'[1]5-4. Calorific&Emission factor'!$P$9:$Y$74,4,FALSE)/1000000)) -> 46937.946 | AV19: =IF($AB19="","",IF(VLOOKUP($AB19,'[1]5-1. Fuel Density'!$B$6:$G$19,6,0)="Use of other GHGs",0,$AS19*VLOOKUP($AB19,'[1]5-4. Calorific&Emission factor'!$P$9:$Y$74,6,FALSE)/1000000)) -> 1.9003217 | AW19: =IF($AB19="","",IF(VLOOKUP($AB19,'[1]5-1. Fuel Density'!$B$6:$G$19,6,0)="Use of other GHGs",0,$AS19*VLOOKUP($AB19,'[1]5-4. Calorific&Emission factor'!$P$9:$Y$74,9,FALSE)/1000000)) -> 0.38006434
B20: 15 | C20: PT. YONGJIN JAVASUKA GARMENT | D20: PT. YONGJIN JAVASUKA GARMENT (2,3공장) | E20: Boiler | F20: Fuel | G20: Stationary combustion | I20: Industrial Wastes | J20: FABRIC WASTE FROM CUTTING | K20: 698000.58 | L20: 60628.782 | M20: 48182.91 | N20: 77836.808 | O20: 55660.545 | P20: 56527.931 | Q20: 76866.122 | R20: 63000.928 | S20: 45761.762 | T20: 43903.11 | U20: 53870.258 | V20: 52157.979 | W20: 63603.443 | X20: kg | Y20: 2022 | Z20: =VLOOKUP($E20,'[1]5-2. Emission Facility'!$B$7:$D$16,2,0) -> Boiler | AA20: =VLOOKUP($Z20,'[1]5-2. Emission Facility'!$C$7:$D$16,2,0) -> Stationary Combustion | AB20: =IF($C20="","",IF(VLOOKUP($C20,'[1]1. General Facility Information'!$C$7:$E$13,3,0)="Korea",'Scope 1'!$I20,INDEX('[1]5-1. Fuel Density'!$B$6:$B$18,MATCH('Scope 1'!$I20,'[1]5-1. Fuel Density'!$C$6:$C$18,0)))) -> Industrial Wastes | AC20: =IF(OR($X20="㎥",$X20="kg"),$L20,"") -> 60628.782 | AD20: =IF(OR($X20="㎥",$X20="kg"),M20,"") -> 48182.91 | AE20: =IF(OR($X20="㎥",$X20="kg"),N20,"") -> 77836.808 | AF20: =IF(OR($X20="㎥",$X20="kg"),O20,"") -> 55660.545 | AG20: =IF(OR($X20="㎥",$X20="kg"),P20,"") -> 56527.931 | AH20: =IF(OR($X20="㎥",$X20="kg"),Q20,"") -> 76866.122 | AI20: =IF(OR($X20="㎥",$X20="kg"),R20,"") -> 63000.928 | AJ20: =IF(OR($X20="㎥",$X20="kg"),S20,"") -> 45761.762 | AK20: =IF(OR($X20="㎥",$X20="kg"),T20,"") -> 43903.11 | ... AN20: =IF(OR($X20="㎥",$X20="kg"),W20,"") -> 63603.443 | AO20: =IF(SUM(AC20:AN20)-AP20=0,"","X") | AP20: =IF(OR($X20="㎥",$X20="kg"),$K20,"") -> 698000.58 | AQ20: =IF(OR($X20="㎥",$X20="kg"),$X20,"") -> kg | AR20: =IF($C20="","",$AP20*IF($AQ20="㎥",VLOOKUP('Scope 1'!AQ20,'[1]5-3. Unit Conversion'!$B$5:$J$13,3,FALSE)*VLOOKUP('Scope 1'!AB20,'[1]5-1. Fuel Density'!$B$6:$D$18,3,FALSE)*1000,IF($AQ20="kg",VLOOKUP('Scope 1'!AQ20,'[1]5-3. Unit Conversion'!$B$16:$G$21,3,FALSE),0))) -> 698000.58 | AS20: =IFERROR(IF($AB20="","",IF(VLOOKUP($AB20,'[1]5-1. Fuel Density'!$B$6:$G$19,6,0)="Use of other GHGs",0,IF($AB20="Industrial Wastes",$AR20*'[1]5-4. Calorific&Emission factor'!$R$75,$AR20*VLOOKUP($AB20,'[1]5-4. Calorific&Emission factor'!$P$9:$R$74,3,FALSE)))),0) -> 15186270 | AT20: =IF($AB20="","",IF(OR($AB20="Hydrofluorocarbons(HFCs)",$AB20="ETC"),$AR20*VLOOKUP($J20,'[1]5-4. Calorific&Emission factor'!$B$10:$D$14,3,0)/1000,IF(VLOOKUP($AB20,'[1]5-1. Fuel Density'!$B$6:$G$19,6,0)="Use of other GHGs",$AU20/1000,(($AU20*'[1]5-4. Calorific&Emission factor'!$D$7)+($AV20*'[1]5-4. Calorific&Emission factor'!$D$8)+($AW20*'[1]5-4. Calorific&Emission factor'!$D$9))/1000))) -> 2200.5209 | AU20: =IF($AB20="","",IF(VLOOKUP($AB20,'[1]5-1. Fuel Density'!$B$6:$G$19,6,0)="Use of other GHGs",$AR20*VLOOKUP($AB20,'[1]5-4. Calorific&Emission factor'!$O$9:$Y$74,5,FALSE)/1000000,$AS20*VLOOKUP($AB20,'[1]5-4. Calorific&Emission factor'!$P$9:$Y$74,4,FALSE)/1000000)) -> 2171636.6 | AV20: =IF($AB20="","",IF(VLOOKUP($AB20,'[1]5-1. Fuel Density'!$B$6:$G$19,6,0)="Use of other GHGs",0,$AS20*VLOOKUP($AB20,'[1]5-4. Calorific&Emission factor'!$P$9:$Y$74,6,FALSE)/1000000)) -> 455.58809 | AW20: =IF($AB20="","",IF(VLOOKUP($AB20,'[1]5-1. Fuel Density'!$B$6:$G$19,6,0)="Use of other GHGs",0,$AS20*VLOOKUP($AB20,'[1]5-4. Calorific&Emission factor'!$P$9:$Y$74,9,FALSE)/1000000)) -> 60.745079
B21: 16 | C21: PT. YONGJIN JAVASUKA GARMENT | D21: PT. YONGJIN JAVASUKA GARMENT (2,3공장) | E21: AC | F21: RawMaterial | G21: Others | I21: Hydrofluorocarbons(HFCs) | J21: HFC-410A | K21: 45.2 | L21: 11.3 | M21: 11.3 | N21: 11.3 | V21: 11.3 | X21: kg | Y21: 2022 | Z21: =VLOOKUP($E21,'[1]5-2. Emission Facility'!$B$7:$D$16,2,0) -> AC | AA21: =VLOOKUP($Z21,'[1]5-2. Emission Facility'!$C$7:$D$16,2,0) -> Process Emissions | AB21: =IF($C21="","",IF(VLOOKUP($C21,'[1]1. General Facility Information'!$C$7:$E$13,3,0)="Korea",'Scope 1'!$I21,INDEX('[1]5-1. Fuel Density'!$B$6:$B$18,MATCH('Scope 1'!$I21,'[1]5-1. Fuel Density'!$C$6:$C$18,0)))) -> Hydrofluorocarbons(HFCs) | AC21: =IF(OR($X21="㎥",$X21="kg"),$L21,"") -> 11.3 | AD21: =IF(OR($X21="㎥",$X21="kg"),M21,"") -> 11.3 | AE21: =IF(OR($X21="㎥",$X21="kg"),N21,"") -> 11.3 | AF21: =IF(OR($X21="㎥",$X21="kg"),O21,"") -> 0 | AG21: =IF(OR($X21="㎥",$X21="kg"),P21,"") -> 0 | AH21: =IF(OR($X21="㎥",$X21="kg"),Q21,"") -> 0 | AI21: =IF(OR($X21="㎥",$X21="kg"),R21,"") -> 0 | AJ21: =IF(OR($X21="㎥",$X21="kg"),S21,"") -> 0 | AK21: =IF(OR($X21="㎥",$X21="kg"),T21,"") -> 0 | ... AN21: =IF(OR($X21="㎥",$X21="kg"),W21,"") -> 0 | AO21: =IF(SUM(AC21:AN21)-AP21=0,"","X") | AP21: =IF(OR($X21="㎥",$X21="kg"),$K21,"") -> 45.2 | AQ21: =IF(OR($X21="㎥",$X21="kg"),$X21,"") -> kg | AR21: =IF($C21="","",$AP21*IF($AQ21="㎥",VLOOKUP('Scope 1'!AQ21,'[1]5-3. Unit Conversion'!$B$5:$J$13,3,FALSE)*VLOOKUP('Scope 1'!AB21,'[1]5-1. Fuel Density'!$B$6:$D$18,3,FALSE)*1000,IF($AQ21="kg",VLOOKUP('Scope 1'!AQ21,'[1]5-3. Unit Conversion'!$B$16:$G$21,3,FALSE),0))) -> 45.2 | AS21: =IFERROR(IF($AB21="","",IF(VLOOKUP($AB21,'[1]5-1. Fuel Density'!$B$6:$G$19,6,0)="Use of other GHGs",0,IF($AB21="Industrial Wastes",$AR21*'[1]5-4. Calorific&Emission factor'!$R$75,$AR21*VLOOKUP($AB21,'[1]5-4. Calorific&Emission factor'!$P$9:$R$74,3,FALSE)))),0) -> 0 | AT21: =IF($AB21="","",IF(OR($AB21="Hydrofluorocarbons(HFCs)",$AB21="ETC"),$AR21*VLOOKUP($J21,'[1]5-4. Calorific&Emission factor'!$B$10:$D$14,3,0)/1000,IF(VLOOKUP($AB21,'[1]5-1. Fuel Density'!$B$6:$G$19,6,0)="Use of other GHGs",$AU21/1000,(($AU21*'[1]5-4. Calorific&Emission factor'!$D$7)+($AV21*'[1]5-4. Calorific&Emission factor'!$D$8)+($AW21*'[1]5-4. Calorific&Emission factor'!$D$9))/1000))) -> 101.9486 | AU21: =IF($AB21="","",IF(VLOOKUP($AB21,'[1]5-1. Fuel Density'!$B$6:$G$19,6,0)="Use of other GHGs",$AR21*VLOOKUP($AB21,'[1]5-4. Calorific&Emission factor'!$O$9:$Y$74,5,FALSE)/1000000,$AS21*VLOOKUP($AB21,'[1]5-4. Calorific&Emission factor'!$P$9:$Y$74,4,FALSE)/1000000)) -> 0 | AV21: =IF($AB21="","",IF(VLOOKUP($AB21,'[1]5-1. Fuel Density'!$B$6:$G$19,6,0)="Use of other GHGs",0,$AS21*VLOOKUP($AB21,'[1]5-4. Calorific&Emission factor'!$P$9:$Y$74,6,FALSE)/1000000)) -> 0 | AW21: =IF($AB21="","",IF(VLOOKUP($AB21,'[1]5-1. Fuel Density'!$B$6:$G$19,6,0)="Use of other GHGs",0,$AS21*VLOOKUP($AB21,'[1]5-4. Calorific&Emission factor'!$P$9:$Y$74,9,FALSE)/1000000)) -> 0
B22: 17 | C22: PT. YONGJIN JAVASUKA GARMENT | D22: PT. YONGJIN JAVASUKA GARMENT (2,3공장) | E22: AC | F22: RawMaterial | G22: Others | I22: ETC | J22: HCFC-22 | K22: 27.2 | V22: 27.2 | X22: kg | Y22: 2022 | Z22: =VLOOKUP($E22,'[1]5-2. Emission Facility'!$B$7:$D$16,2,0) -> AC | AA22: =VLOOKUP($Z22,'[1]5-2. Emission Facility'!$C$7:$D$16,2,0) -> Process Emissions | AB22: =IF($C22="","",IF(VLOOKUP($C22,'[1]1. General Facility Information'!$C$7:$E$13,3,0)="Korea",'Scope 1'!$I22,INDEX('[1]5-1. Fuel Density'!$B$6:$B$18,MATCH('Scope 1'!$I22,'[1]5-1. Fuel Density'!$C$6:$C$18,0)))) -> Hydrofluorocarbons(HFCs) | AC22: =IF(OR($X22="㎥",$X22="kg"),$L22,"") -> 0 | AD22: =IF(OR($X22="㎥",$X22="kg"),M22,"") -> 0 | AE22: =IF(OR($X22="㎥",$X22="kg"),N22,"") -> 0 | AF22: =IF(OR($X22="㎥",$X22="kg"),O22,"") -> 0 | AG22: =IF(OR($X22="㎥",$X22="kg"),P22,"") -> 0 | AH22: =IF(OR($X22="㎥",$X22="kg"),Q22,"") -> 0 | AI22: =IF(OR($X22="㎥",$X22="kg"),R22,"") -> 0 | AJ22: =IF(OR($X22="㎥",$X22="kg"),S22,"") -> 0 | AK22: =IF(OR($X22="㎥",$X22="kg"),T22,"") -> 0 | ... AN22: =IF(OR($X22="㎥",$X22="kg"),W22,"") -> 0 | AO22: =IF(SUM(AC22:AN22)-AP22=0,"","X") | AP22: =IF(OR($X22="㎥",$X22="kg"),$K22,"") -> 27.2 | AQ22: =IF(OR($X22="㎥",$X22="kg"),$X22,"") -> kg | AR22: =IF($C22="","",$AP22*IF($AQ22="㎥",VLOOKUP('Scope 1'!AQ22,'[1]5-3. Unit Conversion'!$B$5:$J$13,3,FALSE)*VLOOKUP('Scope 1'!AB22,'[1]5-1. Fuel Density'!$B$6:$D$18,3,FALSE)*1000,IF($AQ22="kg",VLOOKUP('Scope 1'!AQ22,'[1]5-3. Unit Conversion'!$B$16:$G$21,3,FALSE),0))) -> 27.2 | AS22: =IFERROR(IF($AB22="","",IF(VLOOKUP($AB22,'[1]5-1. Fuel Density'!$B$6:$G$19,6,0)="Use of other GHGs",0,IF($AB22="Industrial Wastes",$AR22*'[1]5-4. Calorific&Emission factor'!$R$75,$AR22*VLOOKUP($AB22,'[1]5-4. Calorific&Emission factor'!$P$9:$R$74,3,FALSE)))),0) -> 0 | AT22: =IF($AB22="","",IF(OR($AB22="Hydrofluorocarbons(HFCs)",$AB22="ETC"),$AR22*VLOOKUP($J22,'[1]5-4. Calorific&Emission factor'!$B$10:$D$14,3,0)/1000,IF(VLOOKUP($AB22,'[1]5-1. Fuel Density'!$B$6:$G$19,6,0)="Use of other GHGs",$AU22/1000,(($AU22*'[1]5-4. Calorific&Emission factor'!$D$7)+($AV22*'[1]5-4. Calorific&Emission factor'!$D$8)+($AW22*'[1]5-4. Calorific&Emission factor'!$D$9))/1000))) -> 53.312 | AU22: =IF($AB22="","",IF(VLOOKUP($AB22,'[1]5-1. Fuel Density'!$B$6:$G$19,6,0)="Use of other GHGs",$AR22*VLOOKUP($AB22,'[1]5-4. Calorific&Emission factor'!$O$9:$Y$74,5,FALSE)/1000000,$AS22*VLOOKUP($AB22,'[1]5-4. Calorific&Emission factor'!$P$9:$Y$74,4,FALSE)/1000000)) -> 0 | AV22: =IF($AB22="","",IF(VLOOKUP($AB22,'[1]5-1. Fuel Density'!$B$6:$G$19,6,0)="Use of other GHGs",0,$AS22*VLOOKUP($AB22,'[1]5-4. Calorific&Emission factor'!$P$9:$Y$74,6,FALSE)/1000000)) -> 0 | AW22: =IF($AB22="","",IF(VLOOKUP($AB22,'[1]5-1. Fuel Density'!$B$6:$G$19,6,0)="Use of other GHGs",0,$AS22*VLOOKUP($AB22,'[1]5-4. Calorific&Emission factor'!$P$9:$Y$74,9,FALSE)/1000000)) -> 0
B23: 18 | C23: PT. YONGJIN JAVASUKA GARMENT | D23: PT. YONGJIN JAVASUKA GARMENT (2,3공장) | E23: AC | F23: RawMaterial | G23: Others | I23: Hydrofluorocarbons(HFCs) | J23: HFC-32 | K23: 10 | M23: 10 | X23: kg | Y23: 2022 | Z23: =VLOOKUP($E23,'[1]5-2. Emission Facility'!$B$7:$D$16,2,0) -> AC | AA23: =VLOOKUP($Z23,'[1]5-2. Emission Facility'!$C$7:$D$16,2,0) -> Process Emissions | AB23: =IF($C23="","",IF(VLOOKUP($C23,'[1]1. General Facility Information'!$C$7:$E$13,3,0)="Korea",'Scope 1'!$I23,INDEX('[1]5-1. Fuel Density'!$B$6:$B$18,MATCH('Scope 1'!$I23,'[1]5-1. Fuel Density'!$C$6:$C$18,0)))) -> Hydrofluorocarbons(HFCs) | AP23: =IF(OR($X23="㎥",$X23="kg"),$K23,"") -> 10 | AQ23: =IF(OR($X23="㎥",$X23="kg"),$X23,"") -> kg | AR23: =IF($C23="","",$AP23*IF($AQ23="㎥",VLOOKUP('Scope 1'!AQ23,'[1]5-3. Unit Conversion'!$B$5:$J$13,3,FALSE)*VLOOKUP('Scope 1'!AB23,'[1]5-1. Fuel Density'!$B$6:$D$18,3,FALSE)*1000,IF($AQ23="kg",VLOOKUP('Scope 1'!AQ23,'[1]5-3. Unit Conversion'!$B$16:$G$21,3,FALSE),0))) -> 10 | AS23: =IFERROR(IF($AB23="","",IF(VLOOKUP($AB23,'[1]5-1. Fuel Density'!$B$6:$G$19,6,0)="Use of other GHGs",0,IF($AB23="Industrial Wastes",$AR23*'[1]5-4. Calorific&Emission factor'!$R$75,$AR23*VLOOKUP($AB23,'[1]5-4. Calorific&Emission factor'!$P$9:$R$74,3,FALSE)))),0) -> 0 | AT23: =IF($AB23="","",IF(OR($AB23="Hydrofluorocarbons(HFCs)",$AB23="ETC"),$AR23*VLOOKUP($J23,'[1]5-4. Calorific&Emission factor'!$B$10:$D$14,3,0)/1000,IF(VLOOKUP($AB23,'[1]5-1. Fuel Density'!$B$6:$G$19,6,0)="Use of other GHGs",$AU23/1000,(($AU23*'[1]5-4. Calorific&Emission factor'!$D$7)+($AV23*'[1]5-4. Calorific&Emission factor'!$D$8)+($AW23*'[1]5-4. Calorific&Emission factor'!$D$9))/1000))) -> 7.71 | AU23: =IF($AB23="","",IF(VLOOKUP($AB23,'[1]5-1. Fuel Density'!$B$6:$G$19,6,0)="Use of other GHGs",$AR23*VLOOKUP($AB23,'[1]5-4. Calorific&Emission factor'!$O$9:$Y$74,5,FALSE)/1000000,$AS23*VLOOKUP($AB23,'[1]5-4. Calorific&Emission factor'!$P$9:$Y$74,4,FALSE)/1000000)) -> 0 | AV23: =IF($AB23="","",IF(VLOOKUP($AB23,'[1]5-1. Fuel Density'!$B$6:$G$19,6,0)="Use of other GHGs",0,$AS23*VLOOKUP($AB23,'[1]5-4. Calorific&Emission factor'!$P$9:$Y$74,6,FALSE)/1000000)) -> 0 | AW23: =IF($AB23="","",IF(VLOOKUP($AB23,'[1]5-1. Fuel Density'!$B$6:$G$19,6,0)="Use of other GHGs",0,$AS23*VLOOKUP($AB23,'[1]5-4. Calorific&Emission factor'!$P$9:$Y$74,9,FALSE)/1000000)) -> 0
