Workbook
Name _______DAT10: #REF!
Name _______DAT10: #REF!
Name _______DAT11: #REF!
Name _______DAT11: #REF!
Name _______DAT12: #REF!
Name _______DAT12: #REF!
Name _______DAT13: #REF!
Name _______DAT14: #REF!
Name _______DAT15: #REF!
Name _______DAT16: #REF!
Name _______DAT17: #REF!
Name _______DAT18: #REF!
Name _______DAT19: #REF!
Name _______DAT2: #REF!
Name _______DAT20: #REF!
Name _______DAT22: #REF!
Name _______DAT23: #REF!
Name _______DAT24: #REF!
Name _______DAT26: #REF!
Name _______DAT27: #REF!
Name _______DAT28: #REF!
Name _______DAT29: #REF!
Name _______DAT3: #REF!
Name _______DAT30: #REF!
Name _______DAT31: #REF!
Name _______DAT32: #REF!
Name _______DAT33: #REF!
Name _______DAT34: #REF!
Name _______DAT35: #REF!
Name _______DAT36: #REF!
Name _______DAT37: #REF!
Name _______DAT38: #REF!
Name _______DAT39: #REF!
Name _______DAT4: #REF!
Name _______DAT40: #REF!
Name _______DAT41: #REF!
Name _______DAT42: #REF!
Name _______DAT43: #REF!
Name _______DAT44: #REF!
Name _______DAT45: #REF!
Name _______DAT46: #REF!
Name _______DAT47: #REF!
Name _______DAT48: #REF!
Name _______DAT5: #REF!
Name _______DAT6: #REF!
Name _______DAT7: #REF!
Name _______DAT8: #REF!
Name _______DAT9: #REF!
Name ______DAT1: #REF!
Name ______DAT10: #REF!
Name ______DAT11: #REF!
Name ______DAT12: #REF!
Name ______DAT13: #REF!
Name ______DAT14: #REF!
Name ______DAT15: #REF!
Name ______DAT16: #REF!
Name ______DAT17: #REF!
Name ______DAT18: #REF!
Name ______DAT19: #REF!
Name ______DAT2: #REF!

Sheet Cover

Sheet 1. General Facility Information
A1: Setting the organizational boundaries of the Hojeon Limited _ General information of the business site
B3: Gernal Infromation of Business Site | G3: Target Business Establishments for Reporting: Business establishments of entities (subsidiaries + affiliates) that are reported as affiliates in the business report of Hojeon Limited. Business establishments where Hojeon Limited has actual operational control, such as those leased, even if not directly owned by Hojeon Limited.
B5: Basic Infromation of Business Site | G5: 사업장 상세정보 | J5: 온실가스 활동 데이터 관리 현황2)
B6: No. | C6: Name of Entity | D6: Name of Facility | E6: Country of Business Location | F6: Business Type | G6: Lease Status | H6: Detailed Address | I6: Area | J6: Greenhouse Gas Emission Sources Under Management3) | K6: Current Status of Management Tools | L6: Department in Charge (Name of the Responsible Person) | M6: Contact Information
B7: 1 | C7: HOJEON LIMITED | D7: HOJEON LIMITED Co., Ltd | E7: Korea | F7: Head Quarters | G7: Ownership | H7: 11th and 12th Floors, Shinhwa Building, 19 Mapo-daero, Mapo-gu, Seoul, Korea | I7: 2,430.2㎡ - 4F(Part), 9F, 11F, 12F, 13F | J7: Scope 1: Vehicles (Mobile Combustion) Scope 2: Electricity, Water Supply | K7: Other (Insert a note if 'Other' is selected) | L7: 박달원 부장, 이소영 과장 | M7: dwpark1@hojeon.co.kr , sylee4@hojeon.co.kr
B8: 2 | C8: PT. KAHOINDAH CITRAGARMENT | D8: KAHOINDAH CITRAGARMENT | E8: Indonesia | F8: Clothing manufacturing factory | G8: Ownership | H8: JI.Bali Blok D16, Kawasan Berikat Nusantara Cilincing Cakung Jakarta Utara, Indonesia | I8: 14,100 M2 (facility) | J8: Scope 1 + Scope 2 | K8: Other (Insert a note if 'Other' is selected) | L8: MS. REZA | M8: reza@kaho.co.id
B9: 3 | C9: PT. YONGJIN JAVASUKA GARMENT | D9: PT. YONGJIN JAVASUKA GARMENT (1공장) | E9: Indonesia | F9: Clothing manufacturing factory | G9: Ownership | H9: JL. RAYA SILLIWANGI KM 35 DESA BUNDA KEC. CICURUG - KAB. SUKABUMI 43359 | I9: Yongjin 1공장 : 21,605 SQM | J9: Scope 1 + Scope 2 | K9: Other (Insert a note if 'Other' is selected) | L9: MS. ANITA | M9: anita@yongjin.co.id
B10: 5 | C10: PT. YONGJIN JAVASUKA GARMENT | D10: PT. YONGJIN JAVASUKA GARMENT (2,3공장) | E10: Indonesia | F10: Clothing manufacturing factory | G10: Ownership | I10: Yongjin 2공장 : 63,266 SQM Yongjin 3공장 : 38,300 SQM
B11: 4 | C11: PT. HJL INDO NETWORKS | D11: PT. HJL INDO NETWORKS | E11: Indonesia | F11: Sales corporation | G11: Ownership | H11: Graha Surveyor Indonesia 17th fl. 1701 Jl. Jend. Gatot Subroto Kav. 56 Jakarta 12950, Indonesia | I11: 1,304 M2 | J11: Scope 1 + Scope 2 (Didn't managed) | K11: Other (Insert a note if 'Other' is selected) | L11: Mr. Fahmi | M11: fahmi@hjl.co.id
B12: 5 | C12: PT.HOGA REKSA GARMENT | D12: PT.HOGA REKSA GARMENT | E12: Indonesia | F12: Clothing manufacturing factory | G12: Ownership | H12: Jl.Raya Leles KM. 13 Kp. Tutugan RT001/ RW. 002 Desa Haruman, Kecamatan Leles, Kabupaten Garut, Jawa Barat. 44152, Indonesia T. +62 0262 2457677 | I12: 125,052 m2 (land) 51,968 m2 (facility) | J12: Scope 1 + Scope 2 | K12: Other (Insert a note if 'Other' is selected) | L12: mr. Andri | M12: andri@hoga.co.id
B13: 6 | C13: ㈜엠파파 | D13: MFAFA Co., Ltd | E13: Korea | F13: Head Quarters | G13: Lease | H13: 13rd Floor, Shinhwa Building, 19 Mapo-daero, Mapo-gu, Seoul, Korea | I13: 66㎡ - 13F(Part) | J13: Scope 2 : Electricty, Water supply | K13: Other (Insert a note if 'Other' is selected) | L13: 박달원 부장, 이소영 과장 | M13: dwpark1@hojeon.co.kr , sylee4@hojeon.co.kr
B17: [Reference] Classification of Greenhouse Gas Emission Sources
B19: Part | D19: Definition | F19: Target
B20: Scope 1 (Direct Emission) | D20: Green House Gas Emissions from sources owned or controlled by the company | F20: Boilers, Furnaces, Turbines, Transportation vehicles, Incinerators Greenhouse gas-emitting chemical processes
B21: Scope 2 (Indirect Enission) | D21: Green House Gas Emissions from the generation of purchased electricity and steam consumed by the company | F21: Electricity and steam purchased or brought into the organizational boundary of the company through other means
B22: Scope 3 (Other Indirect Emissions) | D22: Green House Gas Emissions from activities related to the company, but occurring at facilities not owned or controlled by the company | F22: - Leased assets, Franchises, Outsourced activities - Use of sold products and services - Waste disposal

Sheet 2-1. Quantitative data_Location
B1: HOJEON LIMITED Scope 1,2 Emissions (tCO2eq) (2022~2024) / Location-based
B3: HOJEON LIMITED Annual GHG Emissions for Scope 1&2
B5: 구분 | C5: Scope 1+2 | D5: Scope 1 | H5: Scope 2
B6: Data Collection Year | C6: Total GHG Emissions (tCO2eq) | D6: Fuel Consumption (kg) | E6: Energy Consumption (MJ) | F6: GHG Emissions (tCO2eq) | G6: GHG Emissions Share (%) | H6: Energy Purchased (MJ) | I6: GHG Emissions (tCO2eq) | J6: GHG Emissions Share (%)
B7: 2022 | C7: =F7+I7 -> 17488.362 | D7: =SUMIF('3-1. (Raw data) Scope 1'!$Y:$Y,'2-1. Quantitative data_Location'!$B7,'3-1. (Raw data) Scope 1'!$AR:$AR) -> 1753340.4 | E7: =SUMIF('3-1. (Raw data) Scope 1'!$Y:$Y,'2-1. Quantitative data_Location'!$B7,'3-1. (Raw data) Scope 1'!$AS:$AS) -> 46194039 | F7: =SUMIF('3-1. (Raw data) Scope 1'!$Y:$Y,'2-1. Quantitative data_Location'!$B7,'3-1. (Raw data) Scope 1'!$AT:$AT) -> 5807.3723 | G7: =F7/$C7 -> 0.33207069 | H7: =SUMIF('3-2. (Raw data) Scope2_Location'!$AD:$AD,'2-1. Quantitative data_Location'!$B7,'3-2. (Raw data) Scope2_Location'!$AT:$AT) -> 49010653 | I7: =SUMIF('3-2. (Raw data) Scope2_Location'!$AD:$AD,'2-1. Quantitative data_Location'!$B7,'3-2. (Raw data) Scope2_Location'!$AY:$AY) -> 11680.989 | J7: =I7/$C7 -> 0.66792931
B8: 2023 | C8: =F8+I8 -> 17676.947 | D8: =SUMIF('3-1. (Raw data) Scope 1'!$Y:$Y,'2-1. Quantitative data_Location'!$B8,'3-1. (Raw data) Scope 1'!$AR:$AR) -> 1670455.1 | E8: =SUMIF('3-1. (Raw data) Scope 1'!$Y:$Y,'2-1. Quantitative data_Location'!$B8,'3-1. (Raw data) Scope 1'!$AS:$AS) -> 45214988 | F8: =SUMIF('3-1. (Raw data) Scope 1'!$Y:$Y,'2-1. Quantitative data_Location'!$B8,'3-1. (Raw data) Scope 1'!$AT:$AT) -> 5472.6179 | G8: =F8/$C8 -> 0.30959067 | H8: =SUMIF('3-2. (Raw data) Scope2_Location'!$AD:$AD,'2-1. Quantitative data_Location'!$B8,'3-2. (Raw data) Scope2_Location'!$AT:$AT) -> 51149870 | I8: =SUMIF('3-2. (Raw data) Scope2_Location'!$AD:$AD,'2-1. Quantitative data_Location'!$B8,'3-2. (Raw data) Scope2_Location'!$AY:$AY) -> 12204.329 | J8: =I8/$C8 -> 0.69040933
B9: 2024 | C9: =F9+I9 -> 19499.897 | D9: =SUMIF('3-1. (Raw data) Scope 1'!$Y:$Y,'2-1. Quantitative data_Location'!$B9,'3-1. (Raw data) Scope 1'!$AR:$AR) -> 1648587.9 | E9: =SUMIF('3-1. (Raw data) Scope 1'!$Y:$Y,'2-1. Quantitative data_Location'!$B9,'3-1. (Raw data) Scope 1'!$AS:$AS) -> 43372620 | F9: =SUMIF('3-1. (Raw data) Scope 1'!$Y:$Y,'2-1. Quantitative data_Location'!$B9,'3-1. (Raw data) Scope 1'!$AT:$AT) -> 5415.5677 | G9: =F9/$C9 -> 0.27772289 | H9: =SUMIF('3-2. (Raw data) Scope2_Location'!$AD:$AD,'2-1. Quantitative data_Location'!$B9,'3-2. (Raw data) Scope2_Location'!$AT:$AT) -> 58948770 | I9: =SUMIF('3-2. (Raw data) Scope2_Location'!$AD:$AD,'2-1. Quantitative data_Location'!$B9,'3-2. (Raw data) Scope2_Location'!$AY:$AY) -> 14084.329 | J9: =I9/$C9 -> 0.72227711
B11: HOJEON LIMITED GHG Emissions for Scope 1&2 by Facility
B13: 구분 | C13: Scope 1 + Scope 2 | F13: Scope 1 | I13: Scope 2
B14: Name of Facility | C14: 2022 | D14: 2023 | E14: 2024 | F14: 2022 | G14: 2023 | H14: 2024 | I14: 2022 | J14: 2023 | K14: 2024
B15: Total | C15: =SUM(C16:C22) -> 17488.362 | D15: =SUM(D16:D22) -> 17676.947 | E15: =SUM(E16:E22) -> 19499.897 | F15: =SUM(F16:F22) -> 5807.3723 | G15: =SUM(G16:G22) -> 5472.6179 | H15: =SUM(H16:H22) -> 5415.5677 | I15: =SUM(I16:I22) -> 11680.989 | J15: =SUM(J16:J22) -> 12204.329 | K15: =SUM(K16:K22) -> 14084.329
B16: HOJEON LIMITED Co., Ltd | C16: =F16+I16 -> 235.99585 | D16: =G16+J16 -> 239.15711 | E16: =H16+K16 -> 242.87393 | F16: =D47 -> 49.986937 | G16: =D57 -> 59.95623 | H16: =D67 -> 58.215798 | I16: =K47 -> 186.00891 | J16: =K57 -> 179.20088 | K16: =K67 -> 184.65813
B17: KAHOINDAH CITRAGARMENT | C17: =F17+I17 -> 2538.3389 | D17: =G17+J17 -> 2386.1475 | E17: =H17+K17 -> 2205.9967 | F17: =D48 -> 1092.0335 | G17: =D58 -> 1049.9841 | H17: =D68 -> 877.44929 | I17: =K48 -> 1446.3054 | J17: =K58 -> 1336.1634 | K17: =K68 -> 1328.5474
B18: PT. YONGJIN JAVASUKA GARMENT (1공장) | C18: =F18+I18 -> 2622.4944 | D18: =G18+J18 -> 2504.7999 | E18: =H18+K18 -> 2680.1847 | F18: =D49 -> 1478.1033 | G18: =D59 -> 1377.433 | H18: =D69 -> 1334.7981 | I18: =K49 -> 1144.391 | J18: =K59 -> 1127.3669 | K18: =K69 -> 1345.3866
B19: PT. YONGJIN JAVASUKA GARMENT (2,3공장) | C19: =F19+I19 -> 9864.3183 | D19: =G19+J19 -> 10307.784 | E19: =H19+K19 -> 11041.413 | F19: =D50 -> 3051.6824 | G19: =D60 -> 2809.4554 | H19: =D70 -> 2918.3443 | I19: =K50 -> 6812.6359 | J19: =K60 -> 7498.3282 | K19: =K70 -> 8123.0689
B20: PT. HJL INDO NETWORKS | C20: =F20+I20 -> 91.09388 | D20: =G20+J20 -> 119.04118 | E20: =H20+K20 -> 128.43711 | F20: =D51 -> 71.458589 | G20: =D61 -> 100.83886 | H20: =D71 -> 110.40541 | I20: =K51 -> 19.635291 | J20: =K61 -> 18.202314 | K20: =K71 -> 18.031707
B21: PT.HOGA REKSA GARMENT | C21: =F21+I21 -> 2132.9814 | D21: =G21+J21 -> 2117.4424 | E21: =H21+K21 -> 3198.3873 | F21: =D52 -> 64.107488 | G21: =D62 -> 74.950319 | H21: =D72 -> 116.35485 | I21: =K52 -> 2068.8739 | J21: =K62 -> 2042.492 | K21: =K72 -> 3082.0324
B22: MFAFA Co., Ltd | C22: =F22+I22 -> 3.1390089 | D22: =G22+J22 -> 2.5755052 | E22: =H22+K22 -> 2.6038034 | F22: 0 | G22: 0 | H22: 0 | I22: =K53 -> 3.1390089 | J22: =K63 -> 2.5755052 | K22: =K73 -> 2.6038034
B23: * MFAFA Co., Ltd has been confirmed not to emit Scope 1 energy.
B25: GHG Emissions for Scope 1&2 by Energy Source (tCO2eq)
B27: Scope 1 | C27: Annual GHG Emissions (tCO2eq)
B28: Types of fuel | C28: 2022 | D28: 2023 | E28: 2024
B29: Total | C29: =SUM(C30:C35) -> 5807.3723 | D29: =SUM(D30:D35) -> 5472.6179 | E29: =SUM(E30:E35) -> 5415.5677
B30: {=_xlfn.UNIQUE('3-1. (Raw data) Scope 1'!AB6:AB79)} -> Automotive gasoline (petrol) | C30: =SUMIFS('3-1. (Raw data) Scope 1'!$AT$6:$AT$79,'3-1. (Raw data) Scope 1'!$Y$6:$Y$79,'2-1. Quantitative data_Location'!C$28,'3-1. (Raw data) Scope 1'!$AB$6:$AB$79,'2-1. Quantitative data_Location'!$B30) -> 1034.4686 | D30: =SUMIFS('3-1. (Raw data) Scope 1'!$AT$6:$AT$79,'3-1. (Raw data) Scope 1'!$Y$6:$Y$79,'2-1. Quantitative data_Location'!D$28,'3-1. (Raw data) Scope 1'!$AB$6:$AB$79,'2-1. Quantitative data_Location'!$B30) -> 1098.8887 | E30: =SUMIFS('3-1. (Raw data) Scope 1'!$AT$6:$AT$79,'3-1. (Raw data) Scope 1'!$Y$6:$Y$79,'2-1. Quantitative data_Location'!E$28,'3-1. (Raw data) Scope 1'!$AB$6:$AB$79,'2-1. Quantitative data_Location'!$B30) -> 945.71449
B31: Industrial Wastes | C31: =SUMIFS('3-1. (Raw data) Scope 1'!$AT$6:$AT$79,'3-1. (Raw data) Scope 1'!$Y$6:$Y$79,'2-1. Quantitative data_Location'!C$28,'3-1. (Raw data) Scope 1'!$AB$6:$AB$79,'2-1. Quantitative data_Location'!$B31) -> 4369.6399 | D31: =SUMIFS('3-1. (Raw data) Scope 1'!$AT$6:$AT$79,'3-1. (Raw data) Scope 1'!$Y$6:$Y$79,'2-1. Quantitative data_Location'!D$28,'3-1. (Raw data) Scope 1'!$AB$6:$AB$79,'2-1. Quantitative data_Location'!$B31) -> 3986.6566 | E31: =SUMIFS('3-1. (Raw data) Scope 1'!$AT$6:$AT$79,'3-1. (Raw data) Scope 1'!$Y$6:$Y$79,'2-1. Quantitative data_Location'!E$28,'3-1. (Raw data) Scope 1'!$AB$6:$AB$79,'2-1. Quantitative data_Location'!$B31) -> 4052.7375
B32: Biodiesel | C32: =SUMIFS('3-1. (Raw data) Scope 1'!$AT$6:$AT$79,'3-1. (Raw data) Scope 1'!$Y$6:$Y$79,'2-1. Quantitative data_Location'!C$28,'3-1. (Raw data) Scope 1'!$AB$6:$AB$79,'2-1. Quantitative data_Location'!$B32) -> 23.71627 | D32: =SUMIFS('3-1. (Raw data) Scope 1'!$AT$6:$AT$79,'3-1. (Raw data) Scope 1'!$Y$6:$Y$79,'2-1. Quantitative data_Location'!D$28,'3-1. (Raw data) Scope 1'!$AB$6:$AB$79,'2-1. Quantitative data_Location'!$B32) -> 26.422966 | E32: =SUMIFS('3-1. (Raw data) Scope 1'!$AT$6:$AT$79,'3-1. (Raw data) Scope 1'!$Y$6:$Y$79,'2-1. Quantitative data_Location'!E$28,'3-1. (Raw data) Scope 1'!$AB$6:$AB$79,'2-1. Quantitative data_Location'!$B32) -> 73.41294
B33: Liquefied Petroleum Gas (LPG) | C33: =SUMIFS('3-1. (Raw data) Scope 1'!$AT$6:$AT$79,'3-1. (Raw data) Scope 1'!$Y$6:$Y$79,'2-1. Quantitative data_Location'!C$28,'3-1. (Raw data) Scope 1'!$AB$6:$AB$79,'2-1. Quantitative data_Location'!$B33) -> 8.6025638 | D33: =SUMIFS('3-1. (Raw data) Scope 1'!$AT$6:$AT$79,'3-1. (Raw data) Scope 1'!$Y$6:$Y$79,'2-1. Quantitative data_Location'!D$28,'3-1. (Raw data) Scope 1'!$AB$6:$AB$79,'2-1. Quantitative data_Location'!$B33) -> 7.584198 | E33: =SUMIFS('3-1. (Raw data) Scope 1'!$AT$6:$AT$79,'3-1. (Raw data) Scope 1'!$Y$6:$Y$79,'2-1. Quantitative data_Location'!E$28,'3-1. (Raw data) Scope 1'!$AB$6:$AB$79,'2-1. Quantitative data_Location'!$B33) -> 7.477188
B34: Gas / Diesel oil | C34: =SUMIFS('3-1. (Raw data) Scope 1'!$AT$6:$AT$79,'3-1. (Raw data) Scope 1'!$Y$6:$Y$79,'2-1. Quantitative data_Location'!C$28,'3-1. (Raw data) Scope 1'!$AB$6:$AB$79,'2-1. Quantitative data_Location'!$B34) -> 51.544913 | D34: =SUMIFS('3-1. (Raw data) Scope 1'!$AT$6:$AT$79,'3-1. (Raw data) Scope 1'!$Y$6:$Y$79,'2-1. Quantitative data_Location'!D$28,'3-1. (Raw data) Scope 1'!$AB$6:$AB$79,'2-1. Quantitative data_Location'!$B34) -> 104.75457 | E34: =SUMIFS('3-1. (Raw data) Scope 1'!$AT$6:$AT$79,'3-1. (Raw data) Scope 1'!$Y$6:$Y$79,'2-1. Quantitative data_Location'!E$28,'3-1. (Raw data) Scope 1'!$AB$6:$AB$79,'2-1. Quantitative data_Location'!$B34) -> 48.579677
B35: Hydrofluorocarbons(HFCs) | C35: =SUMIFS('3-1. (Raw data) Scope 1'!$AT$6:$AT$79,'3-1. (Raw data) Scope 1'!$Y$6:$Y$79,'2-1. Quantitative data_Location'!C$28,'3-1. (Raw data) Scope 1'!$AB$6:$AB$79,'2-1. Quantitative data_Location'!$B35) -> 319.40005 | D35: =SUMIFS('3-1. (Raw data) Scope 1'!$AT$6:$AT$79,'3-1. (Raw data) Scope 1'!$Y$6:$Y$79,'2-1. Quantitative data_Location'!D$28,'3-1. (Raw data) Scope 1'!$AB$6:$AB$79,'2-1. Quantitative data_Location'!$B35) -> 248.3109 | E35: =SUMIFS('3-1. (Raw data) Scope 1'!$AT$6:$AT$79,'3-1. (Raw data) Scope 1'!$Y$6:$Y$79,'2-1. Quantitative data_Location'!E$28,'3-1. (Raw data) Scope 1'!$AB$6:$AB$79,'2-1. Quantitative data_Location'!$B35) -> 287.6459
B36: Scope 2 | C36: GHG Emissions (tCO2eq)
B37: Energy sources | C37: 2022 | D37: 2023 | E37: 2024
B38: Total | C38: =SUM(C39:C40) -> 11680.989 | D38: =SUM(D39:D40) -> 12204.329 | E38: =SUM(E39:E40) -> 14084.329
B39: Electricity | C39: =SUMIFS('3-2. (Raw data) Scope2_Location'!$AY:$AY,'3-2. (Raw data) Scope2_Location'!$AD:$AD,'2-1. Quantitative data_Location'!C$37,'3-2. (Raw data) Scope2_Location'!$AE:$AE,$B39) -> 11680.989 | D39: =SUMIFS('3-2. (Raw data) Scope2_Location'!$AY:$AY,'3-2. (Raw data) Scope2_Location'!$AD:$AD,'2-1. Quantitative data_Location'!D$37,'3-2. (Raw data) Scope2_Location'!$AE:$AE,$B39) -> 12204.329 | E39: =SUMIFS('3-2. (Raw data) Scope2_Location'!$AY:$AY,'3-2. (Raw data) Scope2_Location'!$AD:$AD,'2-1. Quantitative data_Location'!E$37,'3-2. (Raw data) Scope2_Location'!$AE:$AE,$B39) -> 14084.329
B40: Steam | C40: =SUMIFS('3-2. (Raw data) Scope2_Location'!$AY:$AY,'3-2. (Raw data) Scope2_Location'!$AD:$AD,'2-1. Quantitative data_Location'!C$37,'3-2. (Raw data) Scope2_Location'!$AE:$AE,$B40) -> 0 | D40: =SUMIFS('3-2. (Raw data) Scope2_Location'!$AY:$AY,'3-2. (Raw data) Scope2_Location'!$AD:$AD,'2-1. Quantitative data_Location'!D$37,'3-2. (Raw data) Scope2_Location'!$AE:$AE,$B40) -> 0 | E40: =SUMIFS('3-2. (Raw data) Scope2_Location'!$AY:$AY,'3-2. (Raw data) Scope2_Location'!$AD:$AD,'2-1. Quantitative data_Location'!E$37,'3-2. (Raw data) Scope2_Location'!$AE:$AE,$B40) -> 0
B42: GHG Emissions for Scope 1&2 by Fuel Type and Facility (tCO2eq)
A44: 2022년 | B44: 2022 | C44: Scope 1 + Scope 2 | D44: Scope 1 | K44: Scope 2
A45: 2022년 | D45: Scope 1 GHG Emissions by Facility | E45: {=_xlfn.TOROW(_xlfn.UNIQUE('3-1. (Raw data) Scope 1'!AB6:AB79))} -> Automotive gasoline (petrol) | F45: Industrial Wastes | G45: Biodiesel | H45: Liquefied Petroleum Gas (LPG) | I45: Gas / Diesel oil | J45: Hydrofluorocarbons(HFCs) | K45: Scope 2 GHG Emissions by Facility | L45: Electricity | M45: Electricity Consumption (MWh)
A46: 2022년 | B46: Total | C46: =D46+K46 -> 17488.362 | D46: =SUM(E46:J46) -> 5807.3723 | E46: =SUM(E47:E53) -> 1034.4686 | F46: =SUM(F47:F53) -> 4369.6399 | G46: =SUM(G47:G53) -> 23.71627 | H46: =SUM(H47:H53) -> 8.6025638 | I46: =SUM(I47:I53) -> 51.544913 | J46: =SUM(J47:J53) -> 319.40005 | K46: =SUM(K47:K53) -> 11680.989 | L46: =SUM(L47:L53) -> 11680.989 | M46: =SUM(M47:M53) -> 13614.07
A47: 2022년 | B47: HOJEON LIMITED Co., Ltd | C47: =D47+K47 -> 235.99585 | D47: =SUM(E47:J47) -> 49.986937 | E47: =SUMIFS('3-1. (Raw data) Scope 1'!$AT$6:$AT$79,'3-1. (Raw data) Scope 1'!$Y$6:$Y$79,'2-1. Quantitative data_Location'!$B$44,'3-1. (Raw data) Scope 1'!$D$6:$D$79,'2-1. Quantitative data_Location'!$B47,'3-1. (Raw data) Scope 1'!$AB$6:$AB$79,'2-1. Quantitative data_Location'!E$45) -> 49.986937 | F47: =SUMIFS('3-1. (Raw data) Scope 1'!$AT$6:$AT$79,'3-1. (Raw data) Scope 1'!$Y$6:$Y$79,'2-1. Quantitative data_Location'!$B$44,'3-1. (Raw data) Scope 1'!$D$6:$D$79,'2-1. Quantitative data_Location'!$B47,'3-1. (Raw data) Scope 1'!$AB$6:$AB$79,'2-1. Quantitative data_Location'!F$45) -> 0 | G47: =SUMIFS('3-1. (Raw data) Scope 1'!$AT$6:$AT$79,'3-1. (Raw data) Scope 1'!$Y$6:$Y$79,'2-1. Quantitative data_Location'!$B$44,'3-1. (Raw data) Scope 1'!$D$6:$D$79,'2-1. Quantitative data_Location'!$B47,'3-1. (Raw data) Scope 1'!$AB$6:$AB$79,'2-1. Quantitative data_Location'!G$45) -> 0 | H47: =SUMIFS('3-1. (Raw data) Scope 1'!$AT$6:$AT$79,'3-1. (Raw data) Scope 1'!$Y$6:$Y$79,'2-1. Quantitative data_Location'!$B$44,'3-1. (Raw data) Scope 1'!$D$6:$D$79,'2-1. Quantitative data_Location'!$B47,'3-1. (Raw data) Scope 1'!$AB$6:$AB$79,'2-1. Quantitative data_Location'!H$45) -> 0 | I47: =SUMIFS('3-1. (Raw data) Scope 1'!$AT$6:$AT$79,'3-1. (Raw data) Scope 1'!$Y$6:$Y$79,'2-1. Quantitative data_Location'!$B$44,'3-1. (Raw data) Scope 1'!$D$6:$D$79,'2-1. Quantitative data_Location'!$B47,'3-1. (Raw data) Scope 1'!$AB$6:$AB$79,'2-1. Quantitative data_Location'!I$45) -> 0 | J47: =SUMIFS('3-1. (Raw data) Scope 1'!$AT$6:$AT$79,'3-1. (Raw data) Scope 1'!$Y$6:$Y$79,'2-1. Quantitative data_Location'!$B$44,'3-1. (Raw data) Scope 1'!$D$6:$D$79,'2-1. Quantitative data_Location'!$B47,'3-1. (Raw data) Scope 1'!$AB$6:$AB$79,'2-1. Quantitative data_Location'!J$45) -> 0 | K47: =SUMIFS('3-2. (Raw data) Scope2_Location'!$AY$6:$AY$33,'3-2. (Raw data) Scope2_Location'!$AD$6:$AD$33,'2-1. Quantitative data_Location'!B$44,'3-2. (Raw data) Scope2_Location'!$D$6:$D$33,'2-1. Quantitative data_Location'!$B47) -> 186.00891 | L47: =SUMIFS('3-2. (Raw data) Scope2_Location'!$AY$6:$AY$33,'3-2. (Raw data) Scope2_Location'!$AD$6:$AD$33,'2-1. Quantitative data_Location'!B$44,'3-2. (Raw data) Scope2_Location'!$D$6:$D$33,'2-1. Quantitative data_Location'!$B47) -> 186.00891 | M47: =SUMIFS('3-2. (Raw data) Scope2_Location'!$AR$6:$AR$33,'3-2. (Raw data) Scope2_Location'!$AD$6:$AD$33,'2-1. Quantitative data_Location'!B$44,'3-2. (Raw data) Scope2_Location'!$D$6:$D$33,'2-1. Quantitative data_Location'!$B47) -> 398.33487
A48: 2022년 | B48: KAHOINDAH CITRAGARMENT | C48: =D48+K48 -> 2538.3389 | D48: =SUM(E48:J48) -> 1092.0335 | E48: =SUMIFS('3-1. (Raw data) Scope 1'!$AT$6:$AT$79,'3-1. (Raw data) Scope 1'!$Y$6:$Y$79,'2-1. Quantitative data_Location'!$B$44,'3-1. (Raw data) Scope 1'!$D$6:$D$79,'2-1. Quantitative data_Location'!$B48,'3-1. (Raw data) Scope 1'!$AB$6:$AB$79,'2-1. Quantitative data_Location'!E$45) -> 69.067883 | F48: =SUMIFS('3-1. (Raw data) Scope 1'!$AT$6:$AT$79,'3-1. (Raw data) Scope 1'!$Y$6:$Y$79,'2-1. Quantitative data_Location'!$B$44,'3-1. (Raw data) Scope 1'!$D$6:$D$79,'2-1. Quantitative data_Location'!$B48,'3-1. (Raw data) Scope 1'!$AB$6:$AB$79,'2-1. Quantitative data_Location'!F$45) -> 1019.5213 | G48: =SUMIFS('3-1. (Raw data) Scope 1'!$AT$6:$AT$79,'3-1. (Raw data) Scope 1'!$Y$6:$Y$79,'2-1. Quantitative data_Location'!$B$44,'3-1. (Raw data) Scope 1'!$D$6:$D$79,'2-1. Quantitative data_Location'!$B48,'3-1. (Raw data) Scope 1'!$AB$6:$AB$79,'2-1. Quantitative data_Location'!G$45) -> 2.512375 | H48: =SUMIFS('3-1. (Raw data) Scope 1'!$AT$6:$AT$79,'3-1. (Raw data) Scope 1'!$Y$6:$Y$79,'2-1. Quantitative data_Location'!$B$44,'3-1. (Raw data) Scope 1'!$D$6:$D$79,'2-1. Quantitative data_Location'!$B48,'3-1. (Raw data) Scope 1'!$AB$6:$AB$79,'2-1. Quantitative data_Location'!H$45) -> 0.9320059 | I48: =SUMIFS('3-1. (Raw data) Scope 1'!$AT$6:$AT$79,'3-1. (Raw data) Scope 1'!$Y$6:$Y$79,'2-1. Quantitative data_Location'!$B$44,'3-1. (Raw data) Scope 1'!$D$6:$D$79,'2-1. Quantitative data_Location'!$B48,'3-1. (Raw data) Scope 1'!$AB$6:$AB$79,'2-1. Quantitative data_Location'!I$45) -> 0 | J48: =SUMIFS('3-1. (Raw data) Scope 1'!$AT$6:$AT$79,'3-1. (Raw data) Scope 1'!$Y$6:$Y$79,'2-1. Quantitative data_Location'!$B$44,'3-1. (Raw data) Scope 1'!$D$6:$D$79,'2-1. Quantitative data_Location'!$B48,'3-1. (Raw data) Scope 1'!$AB$6:$AB$79,'2-1. Quantitative data_Location'!J$45) -> 0 | K48: =SUMIFS('3-2. (Raw data) Scope2_Location'!$AY$6:$AY$33,'3-2. (Raw data) Scope2_Location'!$AD$6:$AD$33,'2-1. Quantitative data_Location'!B$44,'3-2. (Raw data) Scope2_Location'!$D$6:$D$33,'2-1. Quantitative data_Location'!$B48) -> 1446.3054 | L48: =SUMIFS('3-2. (Raw data) Scope2_Location'!$AY$6:$AY$33,'3-2. (Raw data) Scope2_Location'!$AD$6:$AD$33,'2-1. Quantitative data_Location'!B$44,'3-2. (Raw data) Scope2_Location'!$D$6:$D$33,'2-1. Quantitative data_Location'!$B48) -> 1446.3054 | M48: =SUMIFS('3-2. (Raw data) Scope2_Location'!$AR$6:$AR$33,'3-2. (Raw data) Scope2_Location'!$AD$6:$AD$33,'2-1. Quantitative data_Location'!B$44,'3-2. (Raw data) Scope2_Location'!$D$6:$D$33,'2-1. Quantitative data_Location'!$B48) -> 1662.42
...

Sheet 2-2. Quantitative data_Market
B1: HOJEON LIMITED Scope 1,2 Emissions (tCO2eq) (2022~2024) / Market-based
B3: HOJEON LIMITED Annual GHG Emissions for Scope 1&2
B5: 구분 | C5: Scope 1+2 | D5: Scope 1 | H5: Scope 2
B6: Data Collection Year | C6: Total GHG Emissions (tCO2eq) | D6: Fuel Consumption (kg) | E6: Energy Consumption (MJ) | F6: GHG Emissions (tCO2eq) | G6: GHG Emissions Share (%) | H6: Energy Purchased (MJ) | I6: GHG Emissions (tCO2eq) | J6: GHG Emissions Share (%)
B7: 2022 | C7: =F7+I7 -> 17488.362 | D7: =SUMIF('3-1. (Raw data) Scope 1'!$Y:$Y,'2-2. Quantitative data_Market'!$B7,'3-1. (Raw data) Scope 1'!$AR:$AR) -> 1753340.4 | E7: =SUMIF('3-1. (Raw data) Scope 1'!$Y:$Y,'2-2. Quantitative data_Market'!$B7,'3-1. (Raw data) Scope 1'!$AS:$AS) -> 46194039 | F7: =SUMIF('3-1. (Raw data) Scope 1'!$Y:$Y,'2-2. Quantitative data_Market'!$B7,'3-1. (Raw data) Scope 1'!$AT:$AT) -> 5807.3723 | G7: =F7/$C7 -> 0.33207069 | H7: =SUMIF('3-3. (Raw data) Scope 2_Market'!$AD:$AD,'2-2. Quantitative data_Market'!$B7,'3-3. (Raw data) Scope 2_Market'!$AT:$AT) -> 49010653 | I7: =SUMIF('3-3. (Raw data) Scope 2_Market'!$AD:$AD,'2-2. Quantitative data_Market'!$B7,'3-3. (Raw data) Scope 2_Market'!$AY:$AY) -> 11680.989 | J7: =I7/$C7 -> 0.66792931
B8: 2023 | C8: =F8+I8 -> 17676.947 | D8: =SUMIF('3-1. (Raw data) Scope 1'!$Y:$Y,'2-2. Quantitative data_Market'!$B8,'3-1. (Raw data) Scope 1'!$AR:$AR) -> 1670455.1 | E8: =SUMIF('3-1. (Raw data) Scope 1'!$Y:$Y,'2-2. Quantitative data_Market'!$B8,'3-1. (Raw data) Scope 1'!$AS:$AS) -> 45214988 | F8: =SUMIF('3-1. (Raw data) Scope 1'!$Y:$Y,'2-2. Quantitative data_Market'!$B8,'3-1. (Raw data) Scope 1'!$AT:$AT) -> 5472.6179 | G8: =F8/$C8 -> 0.30959067 | H8: =SUMIF('3-3. (Raw data) Scope 2_Market'!$AD:$AD,'2-2. Quantitative data_Market'!$B8,'3-3. (Raw data) Scope 2_Market'!$AT:$AT) -> 51149870 | I8: =SUMIF('3-3. (Raw data) Scope 2_Market'!$AD:$AD,'2-2. Quantitative data_Market'!$B8,'3-3. (Raw data) Scope 2_Market'!$AY:$AY) -> 12204.329 | J8: =I8/$C8 -> 0.69040933
B9: 2024 | C9: =F9+I9 -> 18462.738 | D9: =SUMIF('3-1. (Raw data) Scope 1'!$Y:$Y,'2-2. Quantitative data_Market'!$B9,'3-1. (Raw data) Scope 1'!$AR:$AR) -> 1648587.9 | E9: =SUMIF('3-1. (Raw data) Scope 1'!$Y:$Y,'2-2. Quantitative data_Market'!$B9,'3-1. (Raw data) Scope 1'!$AS:$AS) -> 43372620 | F9: =SUMIF('3-1. (Raw data) Scope 1'!$Y:$Y,'2-2. Quantitative data_Market'!$B9,'3-1. (Raw data) Scope 1'!$AT:$AT) -> 5415.5677 | G9: =F9/$C9 -> 0.29332418 | H9: =SUMIF('3-3. (Raw data) Scope 2_Market'!$AD:$AD,'2-2. Quantitative data_Market'!$B9,'3-3. (Raw data) Scope 2_Market'!$AT:$AT) -> 54657081 | I9: =SUMIF('3-3. (Raw data) Scope 2_Market'!$AD:$AD,'2-2. Quantitative data_Market'!$B9,'3-3. (Raw data) Scope 2_Market'!$AY:$AY) -> 13047.171 | J9: =I9/$C9 -> 0.70667582
B11: HOJEON LIMITED GHG Emissions for Scope 1&2 by Facility
B13: 구분 | C13: Scope 1 + Scope 2 | F13: Scope 1 | I13: Scope 2
B14: Name of Facility | C14: 2022 | D14: 2023 | E14: 2024 | F14: 2022 | G14: 2023 | H14: 2024 | I14: 2022 | J14: 2023 | K14: 2024
B15: Total | C15: =SUM(C16:C22) -> 17488.362 | D15: =SUM(D16:D22) -> 17676.947 | E15: =SUM(E16:E22) -> 17134.191 | F15: =SUM(F16:F22) -> 5807.3723 | G15: =SUM(G16:G22) -> 5472.6179 | H15: =SUM(H16:H22) -> 5415.5677 | I15: =SUM(I16:I22) -> 11680.989 | J15: =SUM(J16:J22) -> 12204.329 | K15: =SUM(K16:K22) -> 11718.623
B16: HOJEON LIMITED Co., Ltd | C16: =F16+I16 -> 235.99585 | D16: =G16+J16 -> 239.15711 | E16: =H16+K16 -> 242.87393 | F16: =D47 -> 49.986937 | G16: =D57 -> 59.95623 | H16: =D67 -> 58.215798 | I16: =K47 -> 186.00891 | J16: =K57 -> 179.20088 | K16: =K67 -> 184.65813
B17: KAHOINDAH CITRAGARMENT | C17: =F17+I17 -> 2538.3389 | D17: =G17+J17 -> 2386.1475 | E17: =H17+K17 -> 877.44929 | F17: =D48 -> 1092.0335 | G17: =D58 -> 1049.9841 | H17: =D68 -> 877.44929 | I17: =K48 -> 1446.3054 | J17: =K58 -> 1336.1634 | K17: =K68 -> 0
B18: PT. YONGJIN JAVASUKA GARMENT (1공장) | C18: =F18+I18 -> 2622.4944 | D18: =G18+J18 -> 2504.7999 | E18: =H18+K18 -> 2549.6847 | F18: =D49 -> 1478.1033 | G18: =D59 -> 1377.433 | H18: =D69 -> 1334.7981 | I18: =K49 -> 1144.391 | J18: =K59 -> 1127.3669 | K18: =K69 -> 1214.8866
B19: PT. YONGJIN JAVASUKA GARMENT (2,3공장) | C19: =F19+I19 -> 9864.3183 | D19: =G19+J19 -> 10307.784 | E19: =H19+K19 -> 10134.755 | F19: =D50 -> 3051.6824 | G19: =D60 -> 2809.4554 | H19: =D70 -> 2918.3443 | I19: =K50 -> 6812.6359 | J19: =K60 -> 7498.3282 | K19: =K70 -> 7216.4106
B20: PT. HJL INDO NETWORKS | C20: =F20+I20 -> 91.09388 | D20: =G20+J20 -> 119.04118 | E20: =H20+K20 -> 128.43711 | F20: =D51 -> 71.458589 | G20: =D61 -> 100.83886 | H20: =D71 -> 110.40541 | I20: =K51 -> 19.635291 | J20: =K61 -> 18.202314 | K20: =K71 -> 18.031707
B21: PT.HOGA REKSA GARMENT | C21: =F21+I21 -> 2132.9814 | D21: =G21+J21 -> 2117.4424 | E21: =H21+K21 -> 3198.3873 | F21: =D52 -> 64.107488 | G21: =D62 -> 74.950319 | H21: =D72 -> 116.35485 | I21: =K52 -> 2068.8739 | J21: =K62 -> 2042.492 | K21: =K72 -> 3082.0324
B22: MFAFA Co., Ltd | C22: =F22+I22 -> 3.1390089 | D22: =G22+J22 -> 2.5755052 | E22: =H22+K22 -> 2.6038034 | F22: 0 | G22: 0 | H22: 0 | I22: =K53 -> 3.1390089 | J22: =K63 -> 2.5755052 | K22: =K73 -> 2.6038034
B23: * MFAFA Co., Ltd has been confirmed not to emit Scope 1 energy.
B25: GHG Emissions for Scope 1&2 by Energy Source (tCO2eq)
B27: Scope 1 | C27: Annual GHG Emissions (tCO2eq)
B28: Types of fuel | C28: 2022 | D28: 2023 | E28: 2024
B29: Total | C29: =SUM(C30:C35) -> 5807.3723 | D29: =SUM(D30:D35) -> 5472.6179 | E29: =SUM(E30:E35) -> 5415.5677
B30: {=_xlfn.UNIQUE('3-1. (Raw data) Scope 1'!AB6:AB79)} -> Automotive gasoline (petrol) | C30: =SUMIFS('3-1. (Raw data) Scope 1'!$AT$6:$AT$79,'3-1. (Raw data) Scope 1'!$Y$6:$Y$79,'2-2. Quantitative data_Market'!C$28,'3-1. (Raw data) Scope 1'!$AB$6:$AB$79,'2-2. Quantitative data_Market'!$B30) -> 1034.4686 | D30: =SUMIFS('3-1. (Raw data) Scope 1'!$AT$6:$AT$79,'3-1. (Raw data) Scope 1'!$Y$6:$Y$79,'2-2. Quantitative data_Market'!D$28,'3-1. (Raw data) Scope 1'!$AB$6:$AB$79,'2-2. Quantitative data_Market'!$B30) -> 1098.8887 | E30: =SUMIFS('3-1. (Raw data) Scope 1'!$AT$6:$AT$79,'3-1. (Raw data) Scope 1'!$Y$6:$Y$79,'2-2. Quantitative data_Market'!E$28,'3-1. (Raw data) Scope 1'!$AB$6:$AB$79,'2-2. Quantitative data_Market'!$B30) -> 945.71449
B31: Industrial Wastes | C31: =SUMIFS('3-1. (Raw data) Scope 1'!$AT$6:$AT$79,'3-1. (Raw data) Scope 1'!$Y$6:$Y$79,'2-2. Quantitative data_Market'!C$28,'3-1. (Raw data) Scope 1'!$AB$6:$AB$79,'2-2. Quantitative data_Market'!$B31) -> 4369.6399 | D31: =SUMIFS('3-1. (Raw data) Scope 1'!$AT$6:$AT$79,'3-1. (Raw data) Scope 1'!$Y$6:$Y$79,'2-2. Quantitative data_Market'!D$28,'3-1. (Raw data) Scope 1'!$AB$6:$AB$79,'2-2. Quantitative data_Market'!$B31) -> 3986.6566 | E31: =SUMIFS('3-1. (Raw data) Scope 1'!$AT$6:$AT$79,'3-1. (Raw data) Scope 1'!$Y$6:$Y$79,'2-2. Quantitative data_Market'!E$28,'3-1. (Raw data) Scope 1'!$AB$6:$AB$79,'2-2. Quantitative data_Market'!$B31) -> 4052.7375
B32: Biodiesel | C32: =SUMIFS('3-1. (Raw data) Scope 1'!$AT$6:$AT$79,'3-1. (Raw data) Scope 1'!$Y$6:$Y$79,'2-2. Quantitative data_Market'!C$28,'3-1. (Raw data) Scope 1'!$AB$6:$AB$79,'2-2. Quantitative data_Market'!$B32) -> 23.71627 | D32: =SUMIFS('3-1. (Raw data) Scope 1'!$AT$6:$AT$79,'3-1. (Raw data) Scope 1'!$Y$6:$Y$79,'2-2. Quantitative data_Market'!D$28,'3-1. (Raw data) Scope 1'!$AB$6:$AB$79,'2-2. Quantitative data_Market'!$B32) -> 26.422966 | E32: =SUMIFS('3-1. (Raw data) Scope 1'!$AT$6:$AT$79,'3-1. (Raw data) Scope 1'!$Y$6:$Y$79,'2-2. Quantitative data_Market'!E$28,'3-1. (Raw data) Scope 1'!$AB$6:$AB$79,'2-2. Quantitative data_Market'!$B32) -> 73.41294
B33: Liquefied Petroleum Gas (LPG) | C33: =SUMIFS('3-1. (Raw data) Scope 1'!$AT$6:$AT$79,'3-1. (Raw data) Scope 1'!$Y$6:$Y$79,'2-2. Quantitative data_Market'!C$28,'3-1. (Raw data) Scope 1'!$AB$6:$AB$79,'2-2. Quantitative data_Market'!$B33) -> 8.6025638 | D33: =SUMIFS('3-1. (Raw data) Scope 1'!$AT$6:$AT$79,'3-1. (Raw data) Scope 1'!$Y$6:$Y$79,'2-2. Quantitative data_Market'!D$28,'3-1. (Raw data) Scope 1'!$AB$6:$AB$79,'2-2. Quantitative data_Market'!$B33) -> 7.584198 | E33: =SUMIFS('3-1. (Raw data) Scope 1'!$AT$6:$AT$79,'3-1. (Raw data) Scope 1'!$Y$6:$Y$79,'2-2. Quantitative data_Market'!E$28,'3-1. (Raw data) Scope 1'!$AB$6:$AB$79,'2-2. Quantitative data_Market'!$B33) -> 7.477188
B34: Gas / Diesel oil | C34: =SUMIFS('3-1. (Raw data) Scope 1'!$AT$6:$AT$79,'3-1. (Raw data) Scope 1'!$Y$6:$Y$79,'2-2. Quantitative data_Market'!C$28,'3-1. (Raw data) Scope 1'!$AB$6:$AB$79,'2-2. Quantitative data_Market'!$B34) -> 51.544913 | D34: =SUMIFS('3-1. (Raw data) Scope 1'!$AT$6:$AT$79,'3-1. (Raw data) Scope 1'!$Y$6:$Y$79,'2-2. Quantitative data_Market'!D$28,'3-1. (Raw data) Scope 1'!$AB$6:$AB$79,'2-2. Quantitative data_Market'!$B34) -> 104.75457 | E34: =SUMIFS('3-1. (Raw data) Scope 1'!$AT$6:$AT$79,'3-1. (Raw data) Scope 1'!$Y$6:$Y$79,'2-2. Quantitative data_Market'!E$28,'3-1. (Raw data) Scope 1'!$AB$6:$AB$79,'2-2. Quantitative data_Market'!$B34) -> 48.579677
B35: Hydrofluorocarbons(HFCs) | C35: =SUMIFS('3-1. (Raw data) Scope 1'!$AT$6:$AT$79,'3-1. (Raw data) Scope 1'!$Y$6:$Y$79,'2-2. Quantitative data_Market'!C$28,'3-1. (Raw data) Scope 1'!$AB$6:$AB$79,'2-2. Quantitative data_Market'!$B35) -> 319.40005 | D35: =SUMIFS('3-1. (Raw data) Scope 1'!$AT$6:$AT$79,'3-1. (Raw data) Scope 1'!$Y$6:$Y$79,'2-2. Quantitative data_Market'!D$28,'3-1. (Raw data) Scope 1'!$AB$6:$AB$79,'2-2. Quantitative data_Market'!$B35) -> 248.3109 | E35: =SUMIFS('3-1. (Raw data) Scope 1'!$AT$6:$AT$79,'3-1. (Raw data) Scope 1'!$Y$6:$Y$79,'2-2. Quantitative data_Market'!E$28,'3-1. (Raw data) Scope 1'!$AB$6:$AB$79,'2-2. Quantitative data_Market'!$B35) -> 287.6459
B36: Scope 2 | C36: GHG Emissions (tCO2eq)
B37: Energy sources | C37: 2022 | D37: 2023 | E37: 2024
B38: Total | C38: =SUM(C39:C40) -> 11680.989 | D38: =SUM(D39:D40) -> 12204.329 | E38: =SUM(E39:E40) -> 13047.171
B39: Electricity | C39: =SUMIFS('3-2. (Raw data) Scope2_Location'!$AY:$AY,'3-2. (Raw data) Scope2_Location'!$AD:$AD,'2-2. Quantitative data_Market'!C$37,'3-2. (Raw data) Scope2_Location'!$AE:$AE,$B39) -> 11680.989 | D39: =SUMIFS('3-2. (Raw data) Scope2_Location'!$AY:$AY,'3-2. (Raw data) Scope2_Location'!$AD:$AD,'2-2. Quantitative data_Market'!D$37,'3-2. (Raw data) Scope2_Location'!$AE:$AE,$B39) -> 12204.329 | E39: =SUMIFS('3-3. (Raw data) Scope 2_Market'!$AY:$AY,'3-3. (Raw data) Scope 2_Market'!$AD:$AD,'2-2. Quantitative data_Market'!E$37,'3-3. (Raw data) Scope 2_Market'!$AE:$AE,$B39) -> 13047.171
B40: Steam | C40: =SUMIFS('3-3. (Raw data) Scope 2_Market'!$AY:$AY,'3-3. (Raw data) Scope 2_Market'!$AD:$AD,'2-2. Quantitative data_Market'!C$37,'3-3. (Raw data) Scope 2_Market'!$AE:$AE,$B40) -> 0 | D40: =SUMIFS('3-2. (Raw data) Scope2_Location'!$AY:$AY,'3-2. (Raw data) Scope2_Location'!$AD:$AD,'2-2. Quantitative data_Market'!D$37,'3-2. (Raw data) Scope2_Location'!$AE:$AE,$B40) -> 0 | E40: =SUMIFS('3-2. (Raw data) Scope2_Location'!$AY:$AY,'3-2. (Raw data) Scope2_Location'!$AD:$AD,'2-2. Quantitative data_Market'!E$37,'3-2. (Raw data) Scope2_Location'!$AE:$AE,$B40) -> 0
B42: GHG Emissions for Scope 1&2 by Fuel Type and Facility (tCO2eq)
A44: 2022년 | B44: 2022 | C44: Scope 1 + Scope 2 | D44: Scope 1 | K44: Scope 2
A45: 2022년 | D45: Scope 1 GHG Emissions by Facility | E45: {=_xlfn.TOROW(_xlfn.UNIQUE('3-1. (Raw data) Scope 1'!AB6:AB79))} -> Automotive gasoline (petrol) | F45: Industrial Wastes | G45: Biodiesel | H45: Liquefied Petroleum Gas (LPG) | I45: Gas / Diesel oil | J45: Hydrofluorocarbons(HFCs) | K45: Scope 2 GHG Emissions by Facility | L45: Electricity | M45: Electricity Consumption (MWh)
A46: 2022년 | B46: Total | C46: =D46+K46 -> 17488.362 | D46: =SUM(E46:J46) -> 5807.3723 | E46: =SUM(E47:E53) -> 1034.4686 | F46: =SUM(F47:F53) -> 4369.6399 | G46: =SUM(G47:G53) -> 23.71627 | H46: =SUM(H47:H53) -> 8.6025638 | I46: =SUM(I47:I53) -> 51.544913 | J46: =SUM(J47:J53) -> 319.40005 | K46: =SUM(K47:K53) -> 11680.989 | L46: =SUM(L47:L53) -> 11680.989 | M46: =SUM(M47:M53) -> 13614.07
A47: 2022년 | B47: {=_xlfn.UNIQUE('3-2. (Raw data) Scope2_Location'!$D$6:$D$33)} -> HOJEON LIMITED Co., Ltd | C47: =D47+K47 -> 235.99585 | D47: =SUM(E47:J47) -> 49.986937 | E47: =SUMIFS('3-1. (Raw data) Scope 1'!$AT$6:$AT$79,'3-1. (Raw data) Scope 1'!$Y$6:$Y$79,'2-2. Quantitative data_Market'!$B$44,'3-1. (Raw data) Scope 1'!$D$6:$D$79,'2-2. Quantitative data_Market'!$B47,'3-1. (Raw data) Scope 1'!$AB$6:$AB$79,'2-2. Quantitative data_Market'!E$45) -> 49.986937 | F47: =SUMIFS('3-1. (Raw data) Scope 1'!$AT$6:$AT$79,'3-1. (Raw data) Scope 1'!$Y$6:$Y$79,'2-2. Quantitative data_Market'!$B$44,'3-1. (Raw data) Scope 1'!$D$6:$D$79,'2-2. Quantitative data_Market'!$B47,'3-1. (Raw data) Scope 1'!$AB$6:$AB$79,'2-2. Quantitative data_Market'!F$45) -> 0 | G47: =SUMIFS('3-1. (Raw data) Scope 1'!$AT$6:$AT$79,'3-1. (Raw data) Scope 1'!$Y$6:$Y$79,'2-2. Quantitative data_Market'!$B$44,'3-1. (Raw data) Scope 1'!$D$6:$D$79,'2-2. Quantitative data_Market'!$B47,'3-1. (Raw data) Scope 1'!$AB$6:$AB$79,'2-2. Quantitative data_Market'!G$45) -> 0 | H47: =SUMIFS('3-1. (Raw data) Scope 1'!$AT$6:$AT$79,'3-1. (Raw data) Scope 1'!$Y$6:$Y$79,'2-2. Quantitative data_Market'!$B$44,'3-1. (Raw data) Scope 1'!$D$6:$D$79,'2-2. Quantitative data_Market'!$B47,'3-1. (Raw data) Scope 1'!$AB$6:$AB$79,'2-2. Quantitative data_Market'!H$45) -> 0 | I47: =SUMIFS('3-1. (Raw data) Scope 1'!$AT$6:$AT$79,'3-1. (Raw data) Scope 1'!$Y$6:$Y$79,'2-2. Quantitative data_Market'!$B$44,'3-1. (Raw data) Scope 1'!$D$6:$D$79,'2-2. Quantitative data_Market'!$B47,'3-1. (Raw data) Scope 1'!$AB$6:$AB$79,'2-2. Quantitative data_Market'!I$45) -> 0 | J47: =SUMIFS('3-1. (Raw data) Scope 1'!$AT$6:$AT$79,'3-1. (Raw data) Scope 1'!$Y$6:$Y$79,'2-2. Quantitative data_Market'!$B$44,'3-1. (Raw data) Scope 1'!$D$6:$D$79,'2-2. Quantitative data_Market'!$B47,'3-1. (Raw data) Scope 1'!$AB$6:$AB$79,'2-2. Quantitative data_Market'!J$45) -> 0 | K47: =SUMIFS('3-2. (Raw data) Scope2_Location'!$AY$6:$AY$33,'3-2. (Raw data) Scope2_Location'!$AD$6:$AD$33,'2-2. Quantitative data_Market'!B$44,'3-2. (Raw data) Scope2_Location'!$D$6:$D$33,'2-2. Quantitative data_Market'!$B47) -> 186.00891 | L47: =SUMIFS('3-2. (Raw data) Scope2_Location'!$AY$6:$AY$33,'3-2. (Raw data) Scope2_Location'!$AD$6:$AD$33,'2-2. Quantitative data_Market'!B$44,'3-2. (Raw data) Scope2_Location'!$D$6:$D$33,'2-2. Quantitative data_Market'!$B47) -> 186.00891 | M47: =SUMIFS('3-2. (Raw data) Scope2_Location'!$AR$6:$AR$33,'3-2. (Raw data) Scope2_Location'!$AD$6:$AD$33,'2-2. Quantitative data_Market'!B$44,'3-2. (Raw data) Scope2_Location'!$D$6:$D$33,'2-2. Quantitative data_Market'!$B47) -> 398.33487
A48: 2022년 | B48: KAHOINDAH CITRAGARMENT | C48: =D48+K48 -> 2538.3389 | D48: =SUM(E48:J48) -> 1092.0335 | E48: =SUMIFS('3-1. (Raw data) Scope 1'!$AT$6:$AT$79,'3-1. (Raw data) Scope 1'!$Y$6:$Y$79,'2-2. Quantitative data_Market'!$B$44,'3-1. (Raw data) Scope 1'!$D$6:$D$79,'2-2. Quantitative data_Market'!$B48,'3-1. (Raw data) Scope 1'!$AB$6:$AB$79,'2-2. Quantitative data_Market'!E$45) -> 69.067883 | F48: =SUMIFS('3-1. (Raw data) Scope 1'!$AT$6:$AT$79,'3-1. (Raw data) Scope 1'!$Y$6:$Y$79,'2-2. Quantitative data_Market'!$B$44,'3-1. (Raw data) Scope 1'!$D$6:$D$79,'2-2. Quantitative data_Market'!$B48,'3-1. (Raw data) Scope 1'!$AB$6:$AB$79,'2-2. Quantitative data_Market'!F$45) -> 1019.5213 | G48: =SUMIFS('3-1. (Raw data) Scope 1'!$AT$6:$AT$79,'3-1. (Raw data) Scope 1'!$Y$6:$Y$79,'2-2. Quantitative data_Market'!$B$44,'3-1. (Raw data) Scope 1'!$D$6:$D$79,'2-2. Quantitative data_Market'!$B48,'3-1. (Raw data) Scope 1'!$AB$6:$AB$79,'2-2. Quantitative data_Market'!G$45) -> 2.512375 | H48: =SUMIFS('3-1. (Raw data) Scope 1'!$AT$6:$AT$79,'3-1. (Raw data) Scope 1'!$Y$6:$Y$79,'2-2. Quantitative data_Market'!$B$44,'3-1. (Raw data) Scope 1'!$D$6:$D$79,'2-2. Quantitative data_Market'!$B48,'3-1. (Raw data) Scope 1'!$AB$6:$AB$79,'2-2. Quantitative data_Market'!H$45) -> 0.9320059 | I48: =SUMIFS('3-1. (Raw data) Scope 1'!$AT$6:$AT$79,'3-1. (Raw data) Scope 1'!$Y$6:$Y$79,'2-2. Quantitative data_Market'!$B$44,'3-1. (Raw data) Scope 1'!$D$6:$D$79,'2-2. Quantitative data_Market'!$B48,'3-1. (Raw data) Scope 1'!$AB$6:$AB$79,'2-2. Quantitative data_Market'!I$45) -> 0 | J48: =SUMIFS('3-1. (Raw data) Scope 1'!$AT$6:$AT$79,'3-1. (Raw data) Scope 1'!$Y$6:$Y$79,'2-2. Quantitative data_Market'!$B$44,'3-1. (Raw data) Scope 1'!$D$6:$D$79,'2-2. Quantitative data_Market'!$B48,'3-1. (Raw data) Scope 1'!$AB$6:$AB$79,'2-2. Quantitative data_Market'!J$45) -> 0 | K48: =SUMIFS('3-2. (Raw data) Scope2_Location'!$AY$6:$AY$33,'3-2. (Raw data) Scope2_Location'!$AD$6:$AD$33,'2-2. Quantitative data_Market'!B$44,'3-2. (Raw data) Scope2_Location'!$D$6:$D$33,'2-2. Quantitative data_Market'!$B48) -> 1446.3054 | L48: =SUMIFS('3-2. (Raw data) Scope2_Location'!$AY$6:$AY$33,'3-2. (Raw data) Scope2_Location'!$AD$6:$AD$33,'2-2. Quantitative data_Market'!B$44,'3-2. (Raw data) Scope2_Location'!$D$6:$D$33,'2-2. Quantitative data_Market'!$B48) -> 1446.3054 | M48: =SUMIFS('3-2. (Raw data) Scope2_Location'!$AR$6:$AR$33,'3-2. (Raw data) Scope2_Location'!$AD$6:$AD$33,'2-2. Quantitative data_Market'!B$44,'3-2. (Raw data) Scope2_Location'!$D$6:$D$33,'2-2. Quantitative data_Market'!$B48) -> 1662.42
...

Sheet (참고} 시각데이터
B1: 2022~2024년 연료 사용량 및 온실가스 배출량 그래프
B4: 2022~2024년 Scope 1+2 온실가스 배출량(tCO2eq)
B6: 호전실업 사업장별 Scope 1+2 온실가스 배출량 | P6: 연료 종류별 Scope 1+2 온실가스 배출량
C8: 데이터 수집년도 | D8: 사업장명 | E8: 데이터 수집범위 | F8: Scope 1 연료 종류 | G8: Scope 2 연료 종류 | Q8: 데이터 수집년도 | S8: 2024년
C9: -선택- | D9: -선택- | E9: -선택- | F9: -선택- | G9: -선택- | Q9: 사업장명 | S9: PT. YONGJIN JAVASUKA GARMENT (2,3공장)
C10: 2022년 | D10: 호전실업 주식회사 | E10: Scope 1 + Scope 2 | F10: {=_xlfn.UNIQUE('3-1. (Raw data) Scope 1'!AB6:AB79)} -> Automotive gasoline (petrol) | G10: 전력
C11: 2023년 | D11: KAHOINDAH CITRAGARMENT | E11: Scope 1 | F11: Industrial Wastes | G11: 스팀 | Q11: Scope 1+2 | R11: Scope 1 | Z11: Scope 2
C12: 2024년 | D12: PT. YONGJIN JAVASUKA GARMENT (1공장) | E12: Scope 2 | F12: Biodiesel | Q12: 합계 | R12: {=_xlfn.TOROW(_xlfn.UNIQUE('3-1. (Raw data) Scope 1'!AB6:AB79))} -> Automotive gasoline (petrol) | S12: Industrial Wastes | T12: Biodiesel | U12: Liquefied Petroleum Gas (LPG) | V12: Gas / Diesel oil | W12: Hydrofluorocarbons(HFCs) | Z12: 전력
D13: PT. YONGJIN JAVASUKA GARMENT (2,3공장) | F13: Liquefied Petroleum Gas (LPG) | O13: ▶ | Q13: =SUM(R13:Z13) -> 0 | R13: =SUMIFS('3-1. (Raw data) Scope 1'!$AT$6:$AT$79,'3-1. (Raw data) Scope 1'!$Y$6:$Y$79,'(참고} 시각데이터'!$S$8,'3-1. (Raw data) Scope 1'!$D$6:$D$79,'(참고} 시각데이터'!$S$9,'3-1. (Raw data) Scope 1'!$AB$6:$AB$79,'(참고} 시각데이터'!R$12) -> 0 | S13: =SUMIFS('3-1. (Raw data) Scope 1'!$AT$6:$AT$79,'3-1. (Raw data) Scope 1'!$Y$6:$Y$79,'(참고} 시각데이터'!$S$8,'3-1. (Raw data) Scope 1'!$D$6:$D$79,'(참고} 시각데이터'!$S$9,'3-1. (Raw data) Scope 1'!$AB$6:$AB$79,'(참고} 시각데이터'!S$12) -> 0 | T13: =SUMIFS('3-1. (Raw data) Scope 1'!$AT$6:$AT$79,'3-1. (Raw data) Scope 1'!$Y$6:$Y$79,'(참고} 시각데이터'!$S$8,'3-1. (Raw data) Scope 1'!$D$6:$D$79,'(참고} 시각데이터'!$S$9,'3-1. (Raw data) Scope 1'!$AB$6:$AB$79,'(참고} 시각데이터'!T$12) -> 0 | U13: =SUMIFS('3-1. (Raw data) Scope 1'!$AT$6:$AT$79,'3-1. (Raw data) Scope 1'!$Y$6:$Y$79,'(참고} 시각데이터'!$S$8,'3-1. (Raw data) Scope 1'!$D$6:$D$79,'(참고} 시각데이터'!$S$9,'3-1. (Raw data) Scope 1'!$AB$6:$AB$79,'(참고} 시각데이터'!U$12) -> 0 | V13: =SUMIFS('3-1. (Raw data) Scope 1'!$AT$6:$AT$79,'3-1. (Raw data) Scope 1'!$Y$6:$Y$79,'(참고} 시각데이터'!$S$8,'3-1. (Raw data) Scope 1'!$D$6:$D$79,'(참고} 시각데이터'!$S$9,'3-1. (Raw data) Scope 1'!$AB$6:$AB$79,'(참고} 시각데이터'!V$12) -> 0 | W13: =SUMIFS('3-1. (Raw data) Scope 1'!$AT$6:$AT$79,'3-1. (Raw data) Scope 1'!$Y$6:$Y$79,'(참고} 시각데이터'!$S$8,'3-1. (Raw data) Scope 1'!$D$6:$D$79,'(참고} 시각데이터'!$S$9,'3-1. (Raw data) Scope 1'!$AB$6:$AB$79,'(참고} 시각데이터'!W$12) -> 0 | X13: =SUMIFS('3-1. (Raw data) Scope 1'!$AT$6:$AT$79,'3-1. (Raw data) Scope 1'!$Y$6:$Y$79,'(참고} 시각데이터'!$S$8,'3-1. (Raw data) Scope 1'!$D$6:$D$79,'(참고} 시각데이터'!$S$9,'3-1. (Raw data) Scope 1'!$AB$6:$AB$79,'(참고} 시각데이터'!X$12) -> 0 | Z13: =SUMIFS('3-2. (Raw data) Scope2_Location'!$AY$6:$AY$33,'3-2. (Raw data) Scope2_Location'!$AD$6:$AD$33,'(참고} 시각데이터'!$S$8,'3-2. (Raw data) Scope2_Location'!$D$6:$D$33,'(참고} 시각데이터'!$S$9,'3-2. (Raw data) Scope2_Location'!$AE$6:$AE$33,'(참고} 시각데이터'!$Z$12) -> 0
D14: PT. HJL INDO NETWORKS | F14: Gas / Diesel oil
D15: PT.HOGA REKSA GARMENT | F15: Hydrofluorocarbons(HFCs)
D16: 주식회사 엠파파
B20: 특이사항 및 확인 필요사항 | D20: - HOGA 사업장의 2024년 배출량 급증 사유 -> 데이터 소수점자리 오기입 수정 完
D21: - YONGJIN 2,3공장의 2024년 Scope 1 배출량 급감 사유 : 산업폐기물의 사용량 급감으로 보이며, 단위 오기입인지 사용량 증가인지 확인 필요
C23: Scope 1+2 | E23: Scope 1 | M23: Scope 2 | Q23: Scope 1+2 | S23: Scope 1 | AA23: Scope 2
C24: 데이터 수집년도 | D24: 합계 | E24: {=_xlfn.TOROW(_xlfn.UNIQUE('3-1. (Raw data) Scope 1'!AB6:AB79))} -> Automotive gasoline (petrol) | F24: Industrial Wastes | G24: Biodiesel | H24: Liquefied Petroleum Gas (LPG) | I24: Gas / Diesel oil | J24: Hydrofluorocarbons(HFCs) | M24: 전력 | Q24: 데이터 수집년도 | R24: 합계 | S24: {=_xlfn.TOROW(_xlfn.UNIQUE('3-1. (Raw data) Scope 1'!AB6:AB79))} -> Automotive gasoline (petrol) | T24: Industrial Wastes | U24: Biodiesel | V24: Liquefied Petroleum Gas (LPG) | W24: Gas / Diesel oil | X24: Hydrofluorocarbons(HFCs) | AA24: 전력
C25: 2022년 | D25: =SUM(E25:M25) -> 0 | E25: =SUMIFS('3-1. (Raw data) Scope 1'!$AT$6:$AT$79,'3-1. (Raw data) Scope 1'!$Y$6:$Y$79,'(참고} 시각데이터'!$C25,'3-1. (Raw data) Scope 1'!$AB$6:$AB$79,E$24) -> 0 | F25: =SUMIFS('3-1. (Raw data) Scope 1'!$AT$6:$AT$79,'3-1. (Raw data) Scope 1'!$Y$6:$Y$79,'(참고} 시각데이터'!$C25,'3-1. (Raw data) Scope 1'!$AB$6:$AB$79,F$24) -> 0 | G25: =SUMIFS('3-1. (Raw data) Scope 1'!$AT$6:$AT$79,'3-1. (Raw data) Scope 1'!$Y$6:$Y$79,'(참고} 시각데이터'!$C25,'3-1. (Raw data) Scope 1'!$AB$6:$AB$79,G$24) -> 0 | H25: =SUMIFS('3-1. (Raw data) Scope 1'!$AT$6:$AT$79,'3-1. (Raw data) Scope 1'!$Y$6:$Y$79,'(참고} 시각데이터'!$C25,'3-1. (Raw data) Scope 1'!$AB$6:$AB$79,H$24) -> 0 | I25: =SUMIFS('3-1. (Raw data) Scope 1'!$AT$6:$AT$79,'3-1. (Raw data) Scope 1'!$Y$6:$Y$79,'(참고} 시각데이터'!$C25,'3-1. (Raw data) Scope 1'!$AB$6:$AB$79,I$24) -> 0 | J25: =SUMIFS('3-1. (Raw data) Scope 1'!$AT$6:$AT$79,'3-1. (Raw data) Scope 1'!$Y$6:$Y$79,'(참고} 시각데이터'!$C25,'3-1. (Raw data) Scope 1'!$AB$6:$AB$79,J$24) -> 0 | K25: =SUMIFS('3-1. (Raw data) Scope 1'!$AT$6:$AT$79,'3-1. (Raw data) Scope 1'!$Y$6:$Y$79,'(참고} 시각데이터'!$C25,'3-1. (Raw data) Scope 1'!$AB$6:$AB$79,K$24) -> 0 | M25: =SUMIFS('3-2. (Raw data) Scope2_Location'!$AY$6:$AY$33,'3-2. (Raw data) Scope2_Location'!$AD$6:$AD$33,'(참고} 시각데이터'!$C25,'3-2. (Raw data) Scope2_Location'!$AE$6:$AE$33,'(참고} 시각데이터'!$M$24) -> 0 | Q25: 2022년 | R25: =SUM(S25:AA25) -> 0 | S25: =SUMIFS('3-1. (Raw data) Scope 1'!$AT$6:$AT$79,'3-1. (Raw data) Scope 1'!$Y$6:$Y$79,'(참고} 시각데이터'!$Q$25,'3-1. (Raw data) Scope 1'!$D$6:$D$79,'(참고} 시각데이터'!$S$9,'3-1. (Raw data) Scope 1'!$AB$6:$AB$79,S$24) -> 0 | T25: =SUMIFS('3-1. (Raw data) Scope 1'!$AT$6:$AT$79,'3-1. (Raw data) Scope 1'!$Y$6:$Y$79,'(참고} 시각데이터'!$Q$25,'3-1. (Raw data) Scope 1'!$D$6:$D$79,'(참고} 시각데이터'!$S$9,'3-1. (Raw data) Scope 1'!$AB$6:$AB$79,'(참고} 시각데이터'!T$24) -> 0 | U25: =SUMIFS('3-1. (Raw data) Scope 1'!$AT$6:$AT$79,'3-1. (Raw data) Scope 1'!$Y$6:$Y$79,'(참고} 시각데이터'!$Q$25,'3-1. (Raw data) Scope 1'!$D$6:$D$79,'(참고} 시각데이터'!$S$9,'3-1. (Raw data) Scope 1'!$AB$6:$AB$79,'(참고} 시각데이터'!U$24) -> 0 | V25: =SUMIFS('3-1. (Raw data) Scope 1'!$AT$6:$AT$79,'3-1. (Raw data) Scope 1'!$Y$6:$Y$79,'(참고} 시각데이터'!$Q$25,'3-1. (Raw data) Scope 1'!$D$6:$D$79,'(참고} 시각데이터'!$S$9,'3-1. (Raw data) Scope 1'!$AB$6:$AB$79,'(참고} 시각데이터'!V$24) -> 0 | W25: =SUMIFS('3-1. (Raw data) Scope 1'!$AT$6:$AT$79,'3-1. (Raw data) Scope 1'!$Y$6:$Y$79,'(참고} 시각데이터'!$Q$25,'3-1. (Raw data) Scope 1'!$D$6:$D$79,'(참고} 시각데이터'!$S$9,'3-1. (Raw data) Scope 1'!$AB$6:$AB$79,'(참고} 시각데이터'!W$24) -> 0 | X25: =SUMIFS('3-1. (Raw data) Scope 1'!$AT$6:$AT$79,'3-1. (Raw data) Scope 1'!$Y$6:$Y$79,'(참고} 시각데이터'!$Q$25,'3-1. (Raw data) Scope 1'!$D$6:$D$79,'(참고} 시각데이터'!$S$9,'3-1. (Raw data) Scope 1'!$AB$6:$AB$79,'(참고} 시각데이터'!X$24) -> 0 | Y25: =SUMIFS('3-1. (Raw data) Scope 1'!$AT$6:$AT$79,'3-1. (Raw data) Scope 1'!$Y$6:$Y$79,'(참고} 시각데이터'!$Q$25,'3-1. (Raw data) Scope 1'!$D$6:$D$79,'(참고} 시각데이터'!$S$9,'3-1. (Raw data) Scope 1'!$AB$6:$AB$79,'(참고} 시각데이터'!Y$24) -> 0 | Z25: =SUMIFS('3-1. (Raw data) Scope 1'!$AT$6:$AT$79,'3-1. (Raw data) Scope 1'!$Y$6:$Y$79,'(참고} 시각데이터'!$Q$25,'3-1. (Raw data) Scope 1'!$D$6:$D$79,'(참고} 시각데이터'!$S$9,'3-1. (Raw data) Scope 1'!$AB$6:$AB$79,'(참고} 시각데이터'!Z$24) -> 0 | AA25: =SUMIFS('3-2. (Raw data) Scope2_Location'!$AY$6:$AY$33,'3-2. (Raw data) Scope2_Location'!$AD$6:$AD$33,'(참고} 시각데이터'!$Q25,'3-2. (Raw data) Scope2_Location'!$D$6:$D$33,'(참고} 시각데이터'!$S$9,'3-2. (Raw data) Scope2_Location'!$AE$6:$AE$33,'(참고} 시각데이터'!$AA$24) -> 0
C26: 2023년 | D26: =SUM(E26:M26) -> 0 | E26: =SUMIFS('3-1. (Raw data) Scope 1'!$AT$6:$AT$79,'3-1. (Raw data) Scope 1'!$Y$6:$Y$79,'(참고} 시각데이터'!$C26,'3-1. (Raw data) Scope 1'!$AB$6:$AB$79,E$24) -> 0 | F26: =SUMIFS('3-1. (Raw data) Scope 1'!$AT$6:$AT$79,'3-1. (Raw data) Scope 1'!$Y$6:$Y$79,'(참고} 시각데이터'!$C26,'3-1. (Raw data) Scope 1'!$AB$6:$AB$79,F$24) -> 0 | G26: =SUMIFS('3-1. (Raw data) Scope 1'!$AT$6:$AT$79,'3-1. (Raw data) Scope 1'!$Y$6:$Y$79,'(참고} 시각데이터'!$C26,'3-1. (Raw data) Scope 1'!$AB$6:$AB$79,G$24) -> 0 | H26: =SUMIFS('3-1. (Raw data) Scope 1'!$AT$6:$AT$79,'3-1. (Raw data) Scope 1'!$Y$6:$Y$79,'(참고} 시각데이터'!$C26,'3-1. (Raw data) Scope 1'!$AB$6:$AB$79,H$24) -> 0 | I26: =SUMIFS('3-1. (Raw data) Scope 1'!$AT$6:$AT$79,'3-1. (Raw data) Scope 1'!$Y$6:$Y$79,'(참고} 시각데이터'!$C26,'3-1. (Raw data) Scope 1'!$AB$6:$AB$79,I$24) -> 0 | J26: =SUMIFS('3-1. (Raw data) Scope 1'!$AT$6:$AT$79,'3-1. (Raw data) Scope 1'!$Y$6:$Y$79,'(참고} 시각데이터'!$C26,'3-1. (Raw data) Scope 1'!$AB$6:$AB$79,J$24) -> 0 | K26: =SUMIFS('3-1. (Raw data) Scope 1'!$AT$6:$AT$79,'3-1. (Raw data) Scope 1'!$Y$6:$Y$79,'(참고} 시각데이터'!$C26,'3-1. (Raw data) Scope 1'!$AB$6:$AB$79,K$24) -> 0 | M26: =SUMIFS('3-2. (Raw data) Scope2_Location'!$AY$6:$AY$33,'3-2. (Raw data) Scope2_Location'!$AD$6:$AD$33,'(참고} 시각데이터'!$C26,'3-2. (Raw data) Scope2_Location'!$AE$6:$AE$33,'(참고} 시각데이터'!$M$24) -> 0 | Q26: 2023년 | R26: =SUM(S26:AA26) -> 0 | S26: =SUMIFS('3-1. (Raw data) Scope 1'!$AT$6:$AT$79,'3-1. (Raw data) Scope 1'!$Y$6:$Y$79,'(참고} 시각데이터'!$Q$25,'3-1. (Raw data) Scope 1'!$D$6:$D$79,'(참고} 시각데이터'!$S$9,'3-1. (Raw data) Scope 1'!$AB$6:$AB$79,S$24) -> 0 | T26: =SUMIFS('3-1. (Raw data) Scope 1'!$AT$6:$AT$79,'3-1. (Raw data) Scope 1'!$Y$6:$Y$79,'(참고} 시각데이터'!$Q$26,'3-1. (Raw data) Scope 1'!$D$6:$D$79,'(참고} 시각데이터'!$S$9,'3-1. (Raw data) Scope 1'!$AB$6:$AB$79,'(참고} 시각데이터'!T$24) -> 0 | U26: =SUMIFS('3-1. (Raw data) Scope 1'!$AT$6:$AT$79,'3-1. (Raw data) Scope 1'!$Y$6:$Y$79,'(참고} 시각데이터'!$Q$26,'3-1. (Raw data) Scope 1'!$D$6:$D$79,'(참고} 시각데이터'!$S$9,'3-1. (Raw data) Scope 1'!$AB$6:$AB$79,'(참고} 시각데이터'!U$24) -> 0 | V26: =SUMIFS('3-1. (Raw data) Scope 1'!$AT$6:$AT$79,'3-1. (Raw data) Scope 1'!$Y$6:$Y$79,'(참고} 시각데이터'!$Q$26,'3-1. (Raw data) Scope 1'!$D$6:$D$79,'(참고} 시각데이터'!$S$9,'3-1. (Raw data) Scope 1'!$AB$6:$AB$79,'(참고} 시각데이터'!V$24) -> 0 | W26: =SUMIFS('3-1. (Raw data) Scope 1'!$AT$6:$AT$79,'3-1. (Raw data) Scope 1'!$Y$6:$Y$79,'(참고} 시각데이터'!$Q$26,'3-1. (Raw data) Scope 1'!$D$6:$D$79,'(참고} 시각데이터'!$S$9,'3-1. (Raw data) Scope 1'!$AB$6:$AB$79,'(참고} 시각데이터'!W$24) -> 0 | X26: =SUMIFS('3-1. (Raw data) Scope 1'!$AT$6:$AT$79,'3-1. (Raw data) Scope 1'!$Y$6:$Y$79,'(참고} 시각데이터'!$Q$26,'3-1. (Raw data) Scope 1'!$D$6:$D$79,'(참고} 시각데이터'!$S$9,'3-1. (Raw data) Scope 1'!$AB$6:$AB$79,'(참고} 시각데이터'!X$24) -> 0 | Y26: =SUMIFS('3-1. (Raw data) Scope 1'!$AT$6:$AT$79,'3-1. (Raw data) Scope 1'!$Y$6:$Y$79,'(참고} 시각데이터'!$Q$25,'3-1. (Raw data) Scope 1'!$D$6:$D$79,'(참고} 시각데이터'!$S$9,'3-1. (Raw data) Scope 1'!$AB$6:$AB$79,'(참고} 시각데이터'!Y$24) -> 0 | Z26: =SUMIFS('3-1. (Raw data) Scope 1'!$AT$6:$AT$79,'3-1. (Raw data) Scope 1'!$Y$6:$Y$79,'(참고} 시각데이터'!$Q$25,'3-1. (Raw data) Scope 1'!$D$6:$D$79,'(참고} 시각데이터'!$S$9,'3-1. (Raw data) Scope 1'!$AB$6:$AB$79,'(참고} 시각데이터'!Z$24) -> 0 | AA26: =SUMIFS('3-2. (Raw data) Scope2_Location'!$AY$6:$AY$33,'3-2. (Raw data) Scope2_Location'!$AD$6:$AD$33,'(참고} 시각데이터'!$Q26,'3-2. (Raw data) Scope2_Location'!$D$6:$D$33,'(참고} 시각데이터'!$S$9,'3-2. (Raw data) Scope2_Location'!$AE$6:$AE$33,'(참고} 시각데이터'!$AA$24) -> 0
C27: 2024년 | D27: =SUM(E27:M27) -> 0 | E27: =SUMIFS('3-1. (Raw data) Scope 1'!$AT$6:$AT$79,'3-1. (Raw data) Scope 1'!$Y$6:$Y$79,'(참고} 시각데이터'!$C27,'3-1. (Raw data) Scope 1'!$AB$6:$AB$79,E$24) -> 0 | F27: =SUMIFS('3-1. (Raw data) Scope 1'!$AT$6:$AT$79,'3-1. (Raw data) Scope 1'!$Y$6:$Y$79,'(참고} 시각데이터'!$C27,'3-1. (Raw data) Scope 1'!$AB$6:$AB$79,F$24) -> 0 | G27: =SUMIFS('3-1. (Raw data) Scope 1'!$AT$6:$AT$79,'3-1. (Raw data) Scope 1'!$Y$6:$Y$79,'(참고} 시각데이터'!$C27,'3-1. (Raw data) Scope 1'!$AB$6:$AB$79,G$24) -> 0 | H27: =SUMIFS('3-1. (Raw data) Scope 1'!$AT$6:$AT$79,'3-1. (Raw data) Scope 1'!$Y$6:$Y$79,'(참고} 시각데이터'!$C27,'3-1. (Raw data) Scope 1'!$AB$6:$AB$79,H$24) -> 0 | I27: =SUMIFS('3-1. (Raw data) Scope 1'!$AT$6:$AT$79,'3-1. (Raw data) Scope 1'!$Y$6:$Y$79,'(참고} 시각데이터'!$C27,'3-1. (Raw data) Scope 1'!$AB$6:$AB$79,I$24) -> 0 | J27: =SUMIFS('3-1. (Raw data) Scope 1'!$AT$6:$AT$79,'3-1. (Raw data) Scope 1'!$Y$6:$Y$79,'(참고} 시각데이터'!$C27,'3-1. (Raw data) Scope 1'!$AB$6:$AB$79,J$24) -> 0 | K27: =SUMIFS('3-1. (Raw data) Scope 1'!$AT$6:$AT$79,'3-1. (Raw data) Scope 1'!$Y$6:$Y$79,'(참고} 시각데이터'!$C27,'3-1. (Raw data) Scope 1'!$AB$6:$AB$79,K$24) -> 0 | M27: =SUMIFS('3-2. (Raw data) Scope2_Location'!$AY$6:$AY$33,'3-2. (Raw data) Scope2_Location'!$AD$6:$AD$33,'(참고} 시각데이터'!$C27,'3-2. (Raw data) Scope2_Location'!$AE$6:$AE$33,'(참고} 시각데이터'!$M$24) -> 0 | Q27: 2024년 | R27: =SUM(S27:AA27) -> 0 | S27: =SUMIFS('3-1. (Raw data) Scope 1'!$AT$6:$AT$79,'3-1. (Raw data) Scope 1'!$Y$6:$Y$79,'(참고} 시각데이터'!$Q$25,'3-1. (Raw data) Scope 1'!$D$6:$D$79,'(참고} 시각데이터'!$S$9,'3-1. (Raw data) Scope 1'!$AB$6:$AB$79,S$24) -> 0 | T27: =SUMIFS('3-1. (Raw data) Scope 1'!$AT$6:$AT$79,'3-1. (Raw data) Scope 1'!$Y$6:$Y$79,'(참고} 시각데이터'!$Q$27,'3-1. (Raw data) Scope 1'!$D$6:$D$79,'(참고} 시각데이터'!$S$9,'3-1. (Raw data) Scope 1'!$AB$6:$AB$79,'(참고} 시각데이터'!T$24) -> 0 | U27: =SUMIFS('3-1. (Raw data) Scope 1'!$AT$6:$AT$79,'3-1. (Raw data) Scope 1'!$Y$6:$Y$79,'(참고} 시각데이터'!$Q$27,'3-1. (Raw data) Scope 1'!$D$6:$D$79,'(참고} 시각데이터'!$S$9,'3-1. (Raw data) Scope 1'!$AB$6:$AB$79,'(참고} 시각데이터'!U$24) -> 0 | V27: =SUMIFS('3-1. (Raw data) Scope 1'!$AT$6:$AT$79,'3-1. (Raw data) Scope 1'!$Y$6:$Y$79,'(참고} 시각데이터'!$Q$27,'3-1. (Raw data) Scope 1'!$D$6:$D$79,'(참고} 시각데이터'!$S$9,'3-1. (Raw data) Scope 1'!$AB$6:$AB$79,'(참고} 시각데이터'!V$24) -> 0 | W27: =SUMIFS('3-1. (Raw data) Scope 1'!$AT$6:$AT$79,'3-1. (Raw data) Scope 1'!$Y$6:$Y$79,'(참고} 시각데이터'!$Q$27,'3-1. (Raw data) Scope 1'!$D$6:$D$79,'(참고} 시각데이터'!$S$9,'3-1. (Raw data) Scope 1'!$AB$6:$AB$79,'(참고} 시각데이터'!W$24) -> 0 | X27: =SUMIFS('3-1. (Raw data) Scope 1'!$AT$6:$AT$79,'3-1. (Raw data) Scope 1'!$Y$6:$Y$79,'(참고} 시각데이터'!$Q$27,'3-1. (Raw data) Scope 1'!$D$6:$D$79,'(참고} 시각데이터'!$S$9,'3-1. (Raw data) Scope 1'!$AB$6:$AB$79,'(참고} 시각데이터'!X$24) -> 0 | Y27: =SUMIFS('3-1. (Raw data) Scope 1'!$AT$6:$AT$79,'3-1. (Raw data) Scope 1'!$Y$6:$Y$79,'(참고} 시각데이터'!$Q$25,'3-1. (Raw data) Scope 1'!$D$6:$D$79,'(참고} 시각데이터'!$S$9,'3-1. (Raw data) Scope 1'!$AB$6:$AB$79,'(참고} 시각데이터'!Y$24) -> 0 | Z27: =SUMIFS('3-1. (Raw data) Scope 1'!$AT$6:$AT$79,'3-1. (Raw data) Scope 1'!$Y$6:$Y$79,'(참고} 시각데이터'!$Q$25,'3-1. (Raw data) Scope 1'!$D$6:$D$79,'(참고} 시각데이터'!$S$9,'3-1. (Raw data) Scope 1'!$AB$6:$AB$79,'(참고} 시각데이터'!Z$24) -> 0 | AA27: =SUMIFS('3-2. (Raw data) Scope2_Location'!$AY$6:$AY$33,'3-2. (Raw data) Scope2_Location'!$AD$6:$AD$33,'(참고} 시각데이터'!$Q27,'3-2. (Raw data) Scope2_Location'!$D$6:$D$33,'(참고} 시각데이터'!$S$9,'3-2. (Raw data) Scope2_Location'!$AE$6:$AE$33,'(참고} 시각데이터'!$AA$24) -> 0
B46: 2022~2024년 Scope 1 온실가스 배출량(tCO2eq)
B48: 호전실업 사업장별 Scope 1 온실가스 배출량 | P48: Scope 1 연료 종류별 온실가스 배출량
Q50: 데이터 수집년도 | S50: 2024년
Q51: 연료 종류 | S51: 자동차용 가솔린(휘발유)
Q53: 합계 | R53: 호전실업 주식회사 | S53: KAHOINDAH CITRAGARMENT | T53: PT. YONGJIN JAVASUKA GARMENT (1공장) | U53: PT. YONGJIN JAVASUKA GARMENT (2,3공장) | V53: PT. HJL INDO NETWORKS | W53: PT.HOGA REKSA GARMENT | X53: 주식회사 엠파파
Q54: =SUM(R54:X54) -> 0 | R54: =SUMIFS('3-1. (Raw data) Scope 1'!$AT$6:$AT$79,'3-1. (Raw data) Scope 1'!$Y$6:$Y$79,'(참고} 시각데이터'!$S$50,'3-1. (Raw data) Scope 1'!$AB$6:$AB$79,'(참고} 시각데이터'!$S$51,'3-1. (Raw data) Scope 1'!$D$6:$D$79,'(참고} 시각데이터'!R$53) -> 0 | S54: =SUMIFS('3-1. (Raw data) Scope 1'!$AT$6:$AT$79,'3-1. (Raw data) Scope 1'!$Y$6:$Y$79,'(참고} 시각데이터'!$S$50,'3-1. (Raw data) Scope 1'!$AB$6:$AB$79,'(참고} 시각데이터'!$S$51,'3-1. (Raw data) Scope 1'!$D$6:$D$79,'(참고} 시각데이터'!S$53) -> 0 | T54: =SUMIFS('3-1. (Raw data) Scope 1'!$AT$6:$AT$79,'3-1. (Raw data) Scope 1'!$Y$6:$Y$79,'(참고} 시각데이터'!$S$50,'3-1. (Raw data) Scope 1'!$AB$6:$AB$79,'(참고} 시각데이터'!$S$51,'3-1. (Raw data) Scope 1'!$D$6:$D$79,'(참고} 시각데이터'!T$53) -> 0 | U54: =SUMIFS('3-1. (Raw data) Scope 1'!$AT$6:$AT$79,'3-1. (Raw data) Scope 1'!$Y$6:$Y$79,'(참고} 시각데이터'!$S$50,'3-1. (Raw data) Scope 1'!$AB$6:$AB$79,'(참고} 시각데이터'!$S$51,'3-1. (Raw data) Scope 1'!$D$6:$D$79,'(참고} 시각데이터'!U$53) -> 0 | V54: =SUMIFS('3-1. (Raw data) Scope 1'!$AT$6:$AT$79,'3-1. (Raw data) Scope 1'!$Y$6:$Y$79,'(참고} 시각데이터'!$S$50,'3-1. (Raw data) Scope 1'!$AB$6:$AB$79,'(참고} 시각데이터'!$S$51,'3-1. (Raw data) Scope 1'!$D$6:$D$79,'(참고} 시각데이터'!V$53) -> 0 | W54: =SUMIFS('3-1. (Raw data) Scope 1'!$AT$6:$AT$79,'3-1. (Raw data) Scope 1'!$Y$6:$Y$79,'(참고} 시각데이터'!$S$50,'3-1. (Raw data) Scope 1'!$AB$6:$AB$79,'(참고} 시각데이터'!$S$51,'3-1. (Raw data) Scope 1'!$D$6:$D$79,'(참고} 시각데이터'!W$53) -> 0 | X54: =SUMIFS('3-1. (Raw data) Scope 1'!$AT$6:$AT$79,'3-1. (Raw data) Scope 1'!$Y$6:$Y$79,'(참고} 시각데이터'!$S$50,'3-1. (Raw data) Scope 1'!$AB$6:$AB$79,'(참고} 시각데이터'!$S$51,'3-1. (Raw data) Scope 1'!$D$6:$D$79,'(참고} 시각데이터'!X$53) -> 0
O55: ▶
B63: 특이사항 | D63: - KAHO 사업장의 배출량이 지속적으로 감소하는 추세
D64: - 엠파파는 Scope 1 배출량 없는 것으로 확인됨
B65: 확인 필요사항 | D65: - YONGJIN 2,3공장의 2023년 Scope 1 배출량 급증 사유 : 수소불화탄소의 사용량 급증으로 보이며, 단위 오기입인지 사용량 증가인지 확인 필요
D66: - 엠파파의 Scope 1 연료 사용여부 확인 필요
B68: 호전실업 사업장별 "S50셀"에서 선택한 Scope 1 연료의 온실가스 배출량 | P68: 호전실업 사업장별 Scope 1 연료 사용량
C70: =Q51 -> 연료 종류 | E70: =S51 -> 자동차용 가솔린(휘발유) | Q70: 사업장명 | S70: PT.HOGA REKSA GARMENT | U70: =Q50 -> 데이터 수집년도 | W70: =S50 -> 2024년 | Y70: =Q51 -> 연료 종류 | AA70: =S51 -> 자동차용 가솔린(휘발유)
C72: =CONCATENATE($E$70," 온실가스 배출량(tCO2eq)") -> 자동차용 가솔린(휘발유) 온실가스 배출량(tCO2eq) | AB72: 단위 : | AC72: =VLOOKUP($S$51,'3-1. (Raw data) Scope 1'!$AB$6:$AQ$79,16,0) -> #N/A
C73: 데이터 수집년도 | D73: 합계 | E73: {=_xlfn.TOROW(_xlfn.UNIQUE(D10:D16))} -> 호전실업 주식회사 | F73: KAHOINDAH CITRAGARMENT | G73: PT. YONGJIN JAVASUKA GARMENT (1공장) | H73: PT. YONGJIN JAVASUKA GARMENT (2,3공장) | I73: PT. HJL INDO NETWORKS | J73: PT.HOGA REKSA GARMENT | K73: 주식회사 엠파파 | Q73: 합계 | R73: 1월 | S73: 2월 | T73: 3월 | U73: 4월 | V73: 5월 | W73: 6월 | X73: 7월 | Y73: 8월 | Z73: 9월 | AA73: 10월 | AB73: 11월 | AC73: 12월
